Workbook
Name ___Cub01: #REF!
Name ___Cub01: #REF!
Name ___Cub01: #REF!
Name ___Fab01: #REF!
Name ___Fab01: #REF!
Name ___Fab01: #REF!
Name ___Fab03: #REF!
Name ___Fab03: #REF!
Name ___Fab03: #REF!
Name ___Fab04: #REF!
Name ___Fab04: #REF!
Name ___Fab04: #REF!
Name ___Fab05: #REF!
Name ___Fab05: #REF!
Name ___Fab05: #REF!
Name ___Fab06: #REF!
Name ___Fab06: #REF!
Name ___Fab06: #REF!
Name ___Try1: [4]!_xlbgnm.Try1
Name __Cub01: #REF!
Name __Cub01: #REF!
Name __Cub01: #REF!
Name __Fab01: #REF!
Name __Fab01: #REF!
Name __Fab01: #REF!
Name __Fab03: #REF!
Name __Fab03: #REF!
Name __Fab03: #REF!
Name __Fab04: #REF!
Name __Fab04: #REF!
Name __Fab04: #REF!
Name __Fab05: #REF!
Name __Fab05: #REF!
Name __Fab05: #REF!
Name __Fab06: #REF!
Name __Fab06: #REF!
Name __Fab06: #REF!
Name __Try1: [4]!_xlbgnm.Try1
Name _412_Office_Supplies: #REF!
Name _412_Office_Supplies: #REF!
Name _412_Office_Supplies: #REF!
Name _421_Facilities_Work_Requests: #REF!
Name _421_Facilities_Work_Requests: #REF!
Name _421_Facilities_Work_Requests: #REF!
Name _422_Spares: #REF!
Name _422_Spares: #REF!
Name _422_Spares: #REF!
Name _424_Equipment_Repair: #REF!
Name _424_Equipment_Repair: #REF!
Name _424_Equipment_Repair: #REF!
Name _425_Preventive_Maint_Contracts: #REF!
Name _425_Preventive_Maint_Contracts: #REF!
Name _425_Preventive_Maint_Contracts: #REF!
Name _661_Facility_Services: #REF!
Name _661_Facility_Services: #REF!
Name _661_Facility_Services: #REF!
Name _BT: 0.0351
Name _Category: '[8]Ref.'!$J$3:$J$6
Name _Cub01: #REF!
Name _Cub01: #REF!

Sheet Overall
B1: PROJECT : ECOCERES SUBSTRUCTURE WORKS | U1: Updated On : | V1: 45422
B2: WEEKLY SCHEDULE & PROGRESS UPDATE | D2: 202375369360256000 and 2116 | I2: PASTE THIS FROM MS PROJECT | K2: 2.2382335e+15
B4: CONTRACTOR | C4: PACKAGE NO | F4: Plan Start | G4: Plan Finish | I4: For Dyna Only | J4: For Dyna Only | K4: SPI | P4: Plan % | T4: Actual % | V4: Delta
B5: DYNACIATE | C5: ECOCERES SUBSTRUCTURE PACKAGE | F5: =F8 -> 45259 | G5: =G8 -> 45350 | K5: =G5-K8 -> -98 | O5: -39 | P5: =T8 -> 1 | T5: =U8 -> 0.9125713 | V5: =V8 -> -0.087428697
B7: Activity ID | C7: Activity Description | D7: Sub sum | E7: Plan Duration | F7: Baseline Start | G7: Baseline Finish | H7: Actual / Forecast Start | K7: Actual / Forecast Finish | L7: Total Quantity | O7: Installed Quantity | P7: Unit | Q7: Plan Units | R7: Cost | S7: Weightage | T7: Plan Prog % | U7: Actual Prog % | V7: Delta | W7: Remark
B8: ECOCERES SUBSTRUCTURE PACKAGE | D8: =SUM(D9,D592,D1036) -> 11395 | E8: =IF(AND(F8<>"",G8<>"",(G8-F8)=0),1,G8-F8+1) -> 92 | F8: 45259 | G8: 45350 | H8: =MIN(H9:H1036) -> 45257 | I8: Start | J8: Finish | K8: =MAX(K9:K1036) -> 45448 | M8: MSP Paste Here | N8: Check Here | S8: =SUM(S9,S592,S1036) -> 1 | T8: =$S9*T9+$S592*T592+$S1036*T1036 -> 1 | U8: =$S9*U9+$S592*U592+$S1036*U1036 -> 0.9125713 | V8: =U8-T8 -> -0.087428697
A9: 147 | B9: UNIT 700, 800 and 900 (SUBSTRUCTURE) | D9: =SUM(D10,D83,D136,D211,D263,D315,D383,D435,D487,D539,D591) -> 8924 | E9: =IF(AND(F9<>"",G9<>"",(G9-F9)=0),1,G9-F9+1) -> 92 | F9: 45259 | G9: 45350 | H9: =I9 -> 45257 | I9: 45257 | J9: 45448 | K9: =J9 -> 45448 | M9: 0.01 | S9: =D9/$D$8 -> 0.7831505 | T9: =$S10*T10+$S83*T83+$S136*T136+$S211*T211+$S263*T263+$S315*T315+$S383*T383+$S435*T435+$S487*T487+$S539*T539+$S591*T591 -> 1 | U9: =$S10*U10+$S83*U83+$S136*U136+$S211*U211+$S263*U263+$S315*U315+$S383*U383+$S435*U435+$S487*U487+$S539*U539+$S591*U591 -> 0.93550538 | V9: =U9-T9 -> -0.064494621
A10: =A9+1 -> 148 | B10: Unit 700 - Auxillary & Tank Yard | D10: =SUM(D11,D14,D82) -> 819 | E10: =IF(AND(F10<>"",G10<>"",(G10-F10)=0),1,G10-F10+1) -> 73 | F10: 45265 | G10: 45337 | H10: =I10 -> 45265 | I10: 45265 | J10: 45448 | K10: =J10 -> 45448 | M10: 0 | S10: =D10/$D$9 -> 0.091774989 | T10: =$S11*T11+$S14*T14+$S82*T82 -> 1 | U10: =$S11*U11+$S14*U14+$S82*U82 -> 0.61471306 | V10: =U10-T10 -> -0.38528694
A11: =A10+1 -> 149 | B11: Piling (Cutting only) | D11: =SUM(D12:D13) -> 7 | E11: =IF(AND(F11<>"",G11<>"",(G11-F11)=0),1,G11-F11+1) -> 7 | F11: 45265 | G11: 45271 | H11: =I11 -> 45265 | I11: 45265 | J11: 45271 | K11: =J11 -> 45271 | M11: 0 | S11: =D11/$D$10 -> 0.0085470085 | T11: {=SUMPRODUCT($S12:$S13*T12:T13)} -> 1 | U11: {=SUMPRODUCT($S12:$S13*U12:U13)} -> 1 | V11: =U11-T11 -> 0
A12: =A11+1 -> 150 | B12: Cutting off Pile to GL | D12: =E12 -> 7 | E12: =IF(AND(F12<>"",G12<>"",(G12-F12)=0),1,G12-F12+1) -> 7 | F12: 45265 | G12: 45271 | H12: =I12 -> 45265 | I12: 45265 | J12: 45271 | K12: =J12 -> 45271 | L12: 100 | M12: 0 | N12: =M12*100 -> 0 | O12: 100 | P12: % | Q12: =IF(OR(F12="",G12="",L12=""),0,MIN(MAX(IF(F12>$V$1,0,(((G12-F12)-(G12-$V$1))*(10/E12)/10)),0),1)*L12) -> 100 | S12: =D12/$D$11 -> 1 | T12: =IF(OR(L12=0,Q12=0),0,Q12/L12) -> 1 | U12: =IF(OR(L12=0,O12=0),0,O12/L12) -> 1 | V12: =U12-T12 -> 0
A13: =A12+1 -> 151 | B13: Completion of Piling | D13: 0 | E13: =IF(AND(F13<>"",G13<>"",(G13-F13)=0),1,G13-F13+1) -> 1 | F13: 45271 | G13: 45271 | H13: =I13 -> 45271 | I13: 45271 | J13: 45271 | K13: =J13 -> 45271 | L13: 100 | M13: 0 | N13: =M13*100 -> 0 | O13: 100 | P13: % | Q13: =IF(OR(F13="",G13="",L13=""),0,MIN(MAX(IF(F13>$V$1,0,(((G13-F13)-(G13-$V$1))*(10/E13)/10)),0),1)*L13) -> 100 | S13: =D13/$D$11 -> 0 | T13: =IF(OR(L13=0,Q13=0),0,Q13/L13) -> 1 | U13: =IF(OR(L13=0,O13=0),0,O13/L13) -> 1 | V13: =U13-T13 -> 0
A14: =A13+1 -> 152 | B14: Substructure | D14: =SUM(D15,D36,D50,D81) -> 812 | E14: =IF(AND(F14<>"",G14<>"",(G14-F14)=0),1,G14-F14+1) -> 62 | F14: 45276 | G14: 45337 | H14: =I14 -> 45313 | I14: 45313 | J14: 45448 | K14: =J14 -> 45448 | M14: 0 | S14: =D14/$D$10 -> 0.99145299 | T14: =$S15*T15+$S36*T36+$S50*T50+$S81*T81 -> 1 | U14: =$S15*U15+$S36*U36+$S50*U50+$S81*U81 -> 0.61139163 | V14: =U14-T14 -> -0.38860837
A15: =A14+1 -> 153 | B15: Structure | D15: =SUM(D16,D27,D35) -> 313 | E15: =IF(AND(F15<>"",G15<>"",(G15-F15)=0),1,G15-F15+1) -> 56 | F15: 45276 | G15: 45331 | H15: =I15 -> 45383 | I15: 45383 | J15: 45448 | K15: =J15 -> 45448 | M15: 0 | S15: =D15/$D$14 -> 0.38546798 | T15: =$S16*T16+$S27*T27+$S35*T35 -> 1 | U15: =$S16*U16+$S27*U27+$S35*U35 -> 0.8798722 | V15: =U15-T15 -> -0.1201278
A16: =A15+1 -> 154 | B16: Pile Cap | D16: =SUM(D17:D26) -> 188 | E16: =IF(AND(F16<>"",G16<>"",(G16-F16)=0),1,G16-F16+1) -> 41 | F16: 45276 | G16: 45316 | H16: =I16 -> 45383 | I16: 45383 | J16: 45433 | K16: =J16 -> 45433 | M16: 0 | S16: =D16/$D$15 -> 0.60063898 | T16: {=SUMPRODUCT($S17:$S26*T17:T26)} -> 1 | U16: {=SUMPRODUCT($S17:$S26*U17:U26)} -> 0.94468085 | V16: =U16-T16 -> -0.055319149
A17: =A16+1 -> 155 | B17: Excavation | D17: =E17 -> 21 | E17: =IF(AND(F17<>"",G17<>"",(G17-F17)=0),1,G17-F17+1) -> 21 | F17: 45276 | G17: 45296 | H17: =I17 -> 45383 | I17: 45383 | J17: 45395 | K17: =J17 -> 45395 | L17: 100 | M17: 0 | N17: =M17*100 -> 0 | O17: 100 | P17: % | Q17: =IF(OR(F17="",G17="",L17=""),0,MIN(MAX(IF(F17>$V$1,0,(((G17-F17)-(G17-$V$1))*(10/E17)/10)),0),1)*L17) -> 100 | S17: =D17/$D$16 -> 0.11170213 | T17: =IF(OR(L17=0,Q17=0),0,Q17/L17) -> 1 | U17: =IF(OR(L17=0,O17=0),0,O17/L17) -> 1 | V17: =U17-T17 -> 0
A18: =A17+1 -> 156 | B18: Leveling and Compaction | D18: =E18 -> 21 | E18: =IF(AND(F18<>"",G18<>"",(G18-F18)=0),1,G18-F18+1) -> 21 | F18: 45279 | G18: 45299 | H18: =I18 -> 45384 | I18: 45384 | J18: 45398 | K18: =J18 -> 45398 | L18: 100 | M18: 0 | N18: =M18*100 -> 0 | O18: 100 | P18: % | Q18: =IF(OR(F18="",G18="",L18=""),0,MIN(MAX(IF(F18>$V$1,0,(((G18-F18)-(G18-$V$1))*(10/E18)/10)),0),1)*L18) -> 100 | S18: =D18/$D$16 -> 0.11170213 | T18: =IF(OR(L18=0,Q18=0),0,Q18/L18) -> 1 | U18: =IF(OR(L18=0,O18=0),0,O18/L18) -> 1 | V18: =U18-T18 -> 0
A19: =A18+1 -> 157 | B19: Lean Concrete Pouring | D19: =E19 -> 21 | E19: =IF(AND(F19<>"",G19<>"",(G19-F19)=0),1,G19-F19+1) -> 21 | F19: 45280 | G19: 45300 | H19: =I19 -> 45387 | I19: 45387 | J19: 45400 | K19: =J19 -> 45400 | L19: 100 | M19: 0 | N19: =M19*100 -> 0 | O19: 100 | P19: % | Q19: =IF(OR(F19="",G19="",L19=""),0,MIN(MAX(IF(F19>$V$1,0,(((G19-F19)-(G19-$V$1))*(10/E19)/10)),0),1)*L19) -> 100 | S19: =D19/$D$16 -> 0.11170213 | T19: =IF(OR(L19=0,Q19=0),0,Q19/L19) -> 1 | U19: =IF(OR(L19=0,O19=0),0,O19/L19) -> 1 | V19: =U19-T19 -> 0
A20: =A19+1 -> 158 | B20: Pile Cutting and Treatment | D20: =E20 -> 21 | E20: =IF(AND(F20<>"",G20<>"",(G20-F20)=0),1,G20-F20+1) -> 21 | F20: 45282 | G20: 45302 | H20: =I20 -> 45387 | I20: 45387 | J20: 45402 | K20: =J20 -> 45402 | L20: 100 | M20: 0 | N20: =M20*100 -> 0 | O20: 100 | P20: % | Q20: =IF(OR(F20="",G20="",L20=""),0,MIN(MAX(IF(F20>$V$1,0,(((G20-F20)-(G20-$V$1))*(10/E20)/10)),0),1)*L20) -> 100 | S20: =D20/$D$16 -> 0.11170213 | T20: =IF(OR(L20=0,Q20=0),0,Q20/L20) -> 1 | U20: =IF(OR(L20=0,O20=0),0,O20/L20) -> 1 | V20: =U20-T20 -> 0
A21: =A20+1 -> 159 | B21: Reinforcement Bar Fixing | D21: =E21 -> 21 | E21: =IF(AND(F21<>"",G21<>"",(G21-F21)=0),1,G21-F21+1) -> 21 | F21: 45286 | G21: 45306 | H21: =I21 -> 45394 | I21: 45394 | J21: 45407 | K21: =J21 -> 45407 | L21: 100 | M21: 0 | N21: =M21*100 -> 0 | O21: 90 | P21: % | Q21: =IF(OR(F21="",G21="",L21=""),0,MIN(MAX(IF(F21>$V$1,0,(((G21-F21)-(G21-$V$1))*(10/E21)/10)),0),1)*L21) -> 100 | S21: =D21/$D$16 -> 0.11170213 | T21: =IF(OR(L21=0,Q21=0),0,Q21/L21) -> 1 | U21: =IF(OR(L21=0,O21=0),0,O21/L21) -> 0.9 | V21: =U21-T21 -> -0.1
A22: =A21+1 -> 160 | B22: Formwork Fixing | D22: =E22 -> 21 | E22: =IF(AND(F22<>"",G22<>"",(G22-F22)=0),1,G22-F22+1) -> 21 | F22: 45289 | G22: 45309 | H22: =I22 -> 45413 | I22: 45413 | J22: 45426 | K22: =J22 -> 45426 | L22: 100 | M22: 0 | N22: =M22*100 -> 0 | O22: 90 | P22: % | Q22: =IF(OR(F22="",G22="",L22=""),0,MIN(MAX(IF(F22>$V$1,0,(((G22-F22)-(G22-$V$1))*(10/E22)/10)),0),1)*L22) -> 100 | S22: =D22/$D$16 -> 0.11170213 | T22: =IF(OR(L22=0,Q22=0),0,Q22/L22) -> 1 | U22: =IF(OR(L22=0,O22=0),0,O22/L22) -> 0.9 | V22: =U22-T22 -> -0.1
A23: =A22+1 -> 161 | B23: Concrete Pouring | D23: =E23 -> 20 | E23: =IF(AND(F23<>"",G23<>"",(G23-F23)=0),1,G23-F23+1) -> 20 | F23: 45292 | G23: 45311 | H23: =I23 -> 45415 | I23: 45415 | J23: 45428 | K23: =J23 -> 45428 | L23: 100 | M23: 0 | N23: =M23*100 -> 0 | O23: 90 | P23: % | Q23: =IF(OR(F23="",G23="",L23=""),0,MIN(MAX(IF(F23>$V$1,0,(((G23-F23)-(G23-$V$1))*(10/E23)/10)),0),1)*L23) -> 100 | S23: =D23/$D$16 -> 0.10638298 | T23: =IF(OR(L23=0,Q23=0),0,Q23/L23) -> 1 | U23: =IF(OR(L23=0,O23=0),0,O23/L23) -> 0.9 | V23: =U23-T23 -> -0.1
A24: =A23+1 -> 162 | B24: Formwork Dismantling | D24: =E24 -> 21 | E24: =IF(AND(F24<>"",G24<>"",(G24-F24)=0),1,G24-F24+1) -> 21 | F24: 45295 | G24: 45315 | H24: =I24 -> 45419 | I24: 45419 | J24: 45432 | K24: =J24 -> 45432 | L24: 100 | M24: 0 | N24: =M24*100 -> 0 | O24: 90 | P24: % | Q24: =IF(OR(F24="",G24="",L24=""),0,MIN(MAX(IF(F24>$V$1,0,(((G24-F24)-(G24-$V$1))*(10/E24)/10)),0),1)*L24) -> 100 | S24: =D24/$D$16 -> 0.11170213 | T24: =IF(OR(L24=0,Q24=0),0,Q24/L24) -> 1 | U24: =IF(OR(L24=0,O24=0),0,O24/L24) -> 0.9 | V24: =U24-T24 -> -0.1
A25: =A24+1 -> 163 | B25: Backfill with compaction | D25: =E25 -> 21 | E25: =IF(AND(F25<>"",G25<>"",(G25-F25)=0),1,G25-F25+1) -> 21 | F25: 45296 | G25: 45316 | H25: =I25 -> 45420 | I25: 45420 | J25: 45433 | K25: =J25 -> 45433 | L25: 100 | M25: 0 | N25: =M25*100 -> 0 | O25: 90 | P25: % | Q25: =IF(OR(F25="",G25="",L25=""),0,MIN(MAX(IF(F25>$V$1,0,(((G25-F25)-(G25-$V$1))*(10/E25)/10)),0),1)*L25) -> 100 | S25: =D25/$D$16 -> 0.11170213 | T25: =IF(OR(L25=0,Q25=0),0,Q25/L25) -> 1 | U25: =IF(OR(L25=0,O25=0),0,O25/L25) -> 0.9 | V25: =U25-T25 -> -0.1
A26: =A25+1 -> 164 | B26: Completion of Pile Cap | D26: 0 | E26: =IF(AND(F26<>"",G26<>"",(G26-F26)=0),1,G26-F26+1) -> 1 | F26: 45316 | G26: 45316 | H26: =I26 -> 45433 | I26: 45433 | J26: 45433 | K26: =J26 -> 45433 | L26: 100 | M26: 0 | N26: =M26*100 -> 0 | P26: % | Q26: =IF(OR(F26="",G26="",L26=""),0,MIN(MAX(IF(F26>$V$1,0,(((G26-F26)-(G26-$V$1))*(10/E26)/10)),0),1)*L26) -> 100 | S26: =D26/$D$16 -> 0 | T26: =IF(OR(L26=0,Q26=0),0,Q26/L26) -> 1 | U26: =IF(OR(L26=0,O26=0),0,O26/L26) -> 0 | V26: =U26-T26 -> -1
A27: =A26+1 -> 165 | B27: Stump | D27: =SUM(D28:D34) -> 125 | E27: =IF(AND(F27<>"",G27<>"",(G27-F27)=0),1,G27-F27+1) -> 33 | F27: 45299 | G27: 45331 | H27: =I27 -> 45422 | I27: 45422 | J27: 45448 | K27: =J27 -> 45448 | M27: 0 | S27: =D27/$D$15 -> 0.39936102 | T27: {=SUMPRODUCT($S28:$S34*T28:T34)} -> 1 | U27: {=SUMPRODUCT($S28:$S34*U28:U34)} -> 0.7824 | V27: =U27-T27 -> -0.2176
A28: =A27+1 -> 166 | B28: Reinforcement Bar Fixing | D28: =E28 -> 20 | E28: =IF(AND(F28<>"",G28<>"",(G28-F28)=0),1,G28-F28+1) -> 20 | F28: 45299 | G28: 45318 | H28: =I28 -> 45422 | I28: 45422 | J28: 45435 | K28: =J28 -> 45435 | L28: 100 | M28: 0 | N28: =M28*100 -> 0 | O28: 90 | P28: % | Q28: =IF(OR(F28="",G28="",L28=""),0,MIN(MAX(IF(F28>$V$1,0,(((G28-F28)-(G28-$V$1))*(10/E28)/10)),0),1)*L28) -> 100 | S28: =D28/$D$27 -> 0.16 | T28: =IF(OR(L28=0,Q28=0),0,Q28/L28) -> 1 | U28: =IF(OR(L28=0,O28=0),0,O28/L28) -> 0.9 | V28: =U28-T28 -> -0.1
A29: =A28+1 -> 167 | B29: Formwork Fixing | D29: =E29 -> 21 | E29: =IF(AND(F29<>"",G29<>"",(G29-F29)=0),1,G29-F29+1) -> 21 | F29: 45301 | G29: 45321 | H29: =I29 -> 45425 | I29: 45425 | J29: 45437 | K29: =J29 -> 45437 | L29: 100 | M29: 0 | N29: =M29*100 -> 0 | O29: 90 | P29: % | Q29: =IF(OR(F29="",G29="",L29=""),0,MIN(MAX(IF(F29>$V$1,0,(((G29-F29)-(G29-$V$1))*(10/E29)/10)),0),1)*L29) -> 100 | S29: =D29/$D$27 -> 0.168 | T29: =IF(OR(L29=0,Q29=0),0,Q29/L29) -> 1 | U29: =IF(OR(L29=0,O29=0),0,O29/L29) -> 0.9 | V29: =U29-T29 -> -0.1
A30: =A29+1 -> 168 | B30: Anchor Bolt Fixing | D30: =E30 -> 21 | E30: =IF(AND(F30<>"",G30<>"",(G30-F30)=0),1,G30-F30+1) -> 21 | F30: 45303 | G30: 45323 | H30: =I30 -> 45427 | I30: 45427 | J30: 45440 | K30: =J30 -> 45440 | L30: 100 | M30: 0 | N30: =M30*100 -> 0 | O30: 90 | P30: % | Q30: =IF(OR(F30="",G30="",L30=""),0,MIN(MAX(IF(F30>$V$1,0,(((G30-F30)-(G30-$V$1))*(10/E30)/10)),0),1)*L30) -> 100 | S30: =D30/$D$27 -> 0.168 | T30: =IF(OR(L30=0,Q30=0),0,Q30/L30) -> 1 | U30: =IF(OR(L30=0,O30=0),0,O30/L30) -> 0.9 | V30: =U30-T30 -> -0.1
A31: =A30+1 -> 169 | B31: Concrete Pouring | D31: =E31 -> 21 | E31: =IF(AND(F31<>"",G31<>"",(G31-F31)=0),1,G31-F31+1) -> 21 | F31: 45307 | G31: 45327 | H31: =I31 -> 45430 | I31: 45430 | J31: 45443 | K31: =J31 -> 45443 | L31: 100 | M31: 0 | N31: =M31*100 -> 0 | O31: 90 | P31: % | Q31: =IF(OR(F31="",G31="",L31=""),0,MIN(MAX(IF(F31>$V$1,0,(((G31-F31)-(G31-$V$1))*(10/E31)/10)),0),1)*L31) -> 100 | S31: =D31/$D$27 -> 0.168 | T31: =IF(OR(L31=0,Q31=0),0,Q31/L31) -> 1 | U31: =IF(OR(L31=0,O31=0),0,O31/L31) -> 0.9 | V31: =U31-T31 -> -0.1
A32: =A31+1 -> 170 | B32: Formwork Dismantling | D32: =E32 -> 21 | E32: =IF(AND(F32<>"",G32<>"",(G32-F32)=0),1,G32-F32+1) -> 21 | F32: 45310 | G32: 45330 | H32: =I32 -> 45434 | I32: 45434 | J32: 45447 | K32: =J32 -> 45447 | L32: 100 | M32: 0 | N32: =M32*100 -> 0 | O32: 90 | P32: % | Q32: =IF(OR(F32="",G32="",L32=""),0,MIN(MAX(IF(F32>$V$1,0,(((G32-F32)-(G32-$V$1))*(10/E32)/10)),0),1)*L32) -> 100 | S32: =D32/$D$27 -> 0.168 | T32: =IF(OR(L32=0,Q32=0),0,Q32/L32) -> 1 | U32: =IF(OR(L32=0,O32=0),0,O32/L32) -> 0.9 | V32: =U32-T32 -> -0.1
A33: =A32+1 -> 171 | B33: Backfill with compaction | D33: =E33 -> 21 | E33: =IF(AND(F33<>"",G33<>"",(G33-F33)=0),1,G33-F33+1) -> 21 | F33: 45311 | G33: 45331 | H33: =I33 -> 45435 | I33: 45435 | J33: 45448 | K33: =J33 -> 45448 | L33: 100 | M33: 0 | N33: =M33*100 -> 0 | O33: 20 | P33: % | Q33: =IF(OR(F33="",G33="",L33=""),0,MIN(MAX(IF(F33>$V$1,0,(((G33-F33)-(G33-$V$1))*(10/E33)/10)),0),1)*L33) -> 100 | S33: =D33/$D$27 -> 0.168 | T33: =IF(OR(L33=0,Q33=0),0,Q33/L33) -> 1 | U33: =IF(OR(L33=0,O33=0),0,O33/L33) -> 0.2 | V33: =U33-T33 -> -0.8
A34: =A33+1 -> 172 | B34: Completion of Stump | D34: 0 | E34: =IF(AND(F34<>"",G34<>"",(G34-F34)=0),1,G34-F34+1) -> 1 | F34: 45331 | G34: 45331 | H34: =I34 -> 45448 | I34: 45448 | J34: 45448 | K34: =J34 -> 45448 | L34: 100 | M34: 0 | N34: =M34*100 -> 0 | P34: % | Q34: =IF(OR(F34="",G34="",L34=""),0,MIN(MAX(IF(F34>$V$1,0,(((G34-F34)-(G34-$V$1))*(10/E34)/10)),0),1)*L34) -> 100 | S34: =D34/$D$27 -> 0 | T34: =IF(OR(L34=0,Q34=0),0,Q34/L34) -> 1 | U34: =IF(OR(L34=0,O34=0),0,O34/L34) -> 0 | V34: =U34-T34 -> -1
A35: =A34+1 -> 173 | B35: Completion of Structure | D35: 0 | E35: =IF(AND(F35<>"",G35<>"",(G35-F35)=0),1,G35-F35+1) -> 1 | F35: 45331 | G35: 45331 | H35: =I35 -> 45448 | I35: 45448 | J35: 45448 | K35: =J35 -> 45448 | L35: 100 | M35: 0 | N35: =M35*100 -> 0 | P35: % | Q35: =IF(OR(F35="",G35="",L35=""),0,MIN(MAX(IF(F35>$V$1,0,(((G35-F35)-(G35-$V$1))*(10/E35)/10)),0),1)*L35) -> 100 | S35: =D35/$D$15 -> 0 | T35: =IF(OR(L35=0,Q35=0),0,Q35/L35) -> 1 | U35: =IF(OR(L35=0,O35=0),0,O35/L35) -> 0 | V35: =U35-T35 -> -1
A36: =A35+1 -> 174 | B36: Tank / Equipment and Pump Foundation | D36: =SUM(D37,D49) -> 185 | E36: =IF(AND(F36<>"",G36<>"",(G36-F36)=0),1,G36-F36+1) -> 42 | F36: 45296 | G36: 45337 | H36: =I36 -> 45316 | I36: 45316 | J36: 45374 | K36: =J36 -> 45374 | M36: 0 | S36: =D36/$D$14 -> 0.22783251 | T36: =$S37*T37+$S49*T49 -> 1 | U36: =$S37*U37+$S49*U49 -> 1 | V36: =U36-T36 -> 0
A37: =A36+1 -> 175 | B37: Tank / Equipment Foundation | D37: =SUM(D38:D48) -> 185 | E37: =IF(AND(F37<>"",G37<>"",(G37-F37)=0),1,G37-F37+1) -> 42 | F37: 45296 | G37: 45337 | H37: =I37 -> 45316 | I37: 45316 | J37: 45374 | K37: =J37 -> 45374 | M37: 0 | S37: =D37/$D$36 -> 1 | T37: {=SUMPRODUCT($S38:$S48*T38:T48)} -> 1 | U37: {=SUMPRODUCT($S38:$S48*U38:U48)} -> 1 | V37: =U37-T37 -> 0
A38: =A37+1 -> 176 | B38: Excavation | D38: =E38 -> 19 | E38: =IF(AND(F38<>"",G38<>"",(G38-F38)=0),1,G38-F38+1) -> 19 | F38: 45296 | G38: 45314 | H38: =I38 -> 45316 | I38: 45316 | J38: 45334 | K38: =J38 -> 45334 | L38: 100 | M38: 0 | N38: =M38*100 -> 0 | O38: 100 | P38: % | Q38: =IF(OR(F38="",G38="",L38=""),0,MIN(MAX(IF(F38>$V$1,0,(((G38-F38)-(G38-$V$1))*(10/E38)/10)),0),1)*L38) -> 100 | S38: =D38/$D$37 -> 0.1027027 | T38: =IF(OR(L38=0,Q38=0),0,Q38/L38) -> 1 | U38: =IF(OR(L38=0,O38=0),0,O38/L38) -> 1 | V38: =U38-T38 -> 0
A39: =A38+1 -> 177 | B39: Leveling and Compaction | D39: =E39 -> 18 | E39: =IF(AND(F39<>"",G39<>"",(G39-F39)=0),1,G39-F39+1) -> 18 | F39: 45299 | G39: 45316 | H39: =I39 -> 45325 | I39: 45325 | J39: 45335 | K39: =J39 -> 45335 | L39: 100 | M39: 0 | N39: =M39*100 -> 0 | O39: 100 | P39: % | Q39: =IF(OR(F39="",G39="",L39=""),0,MIN(MAX(IF(F39>$V$1,0,(((G39-F39)-(G39-$V$1))*(10/E39)/10)),0),1)*L39) -> 100 | S39: =D39/$D$37 -> 0.097297297 | T39: =IF(OR(L39=0,Q39=0),0,Q39/L39) -> 1 | U39: =IF(OR(L39=0,O39=0),0,O39/L39) -> 1 | V39: =U39-T39 -> 0
A40: =A39+1 -> 178 | B40: Lean Concrete Pouring | D40: =E40 -> 18 | E40: =IF(AND(F40<>"",G40<>"",(G40-F40)=0),1,G40-F40+1) -> 18 | F40: 45300 | G40: 45317 | H40: =I40 -> 45328 | I40: 45328 | J40: 45341 | K40: =J40 -> 45341 | L40: 100 | M40: 0 | N40: =M40*100 -> 0 | O40: 100 | P40: % | Q40: =IF(OR(F40="",G40="",L40=""),0,MIN(MAX(IF(F40>$V$1,0,(((G40-F40)-(G40-$V$1))*(10/E40)/10)),0),1)*L40) -> 100 | S40: =D40/$D$37 -> 0.097297297 | T40: =IF(OR(L40=0,Q40=0),0,Q40/L40) -> 1 | U40: =IF(OR(L40=0,O40=0),0,O40/L40) -> 1 | V40: =U40-T40 -> 0
A41: =A40+1 -> 179 | B41: Pile Cutting and Treatment | D41: =E41 -> 19 | E41: =IF(AND(F41<>"",G41<>"",(G41-F41)=0),1,G41-F41+1) -> 19 | F41: 45302 | G41: 45320 | H41: =I41 -> 45329 | I41: 45329 | J41: 45342 | K41: =J41 -> 45342 | L41: 100 | M41: 0 | N41: =M41*100 -> 0 | O41: 100 | P41: % | Q41: =IF(OR(F41="",G41="",L41=""),0,MIN(MAX(IF(F41>$V$1,0,(((G41-F41)-(G41-$V$1))*(10/E41)/10)),0),1)*L41) -> 100 | S41: =D41/$D$37 -> 0.1027027 | T41: =IF(OR(L41=0,Q41=0),0,Q41/L41) -> 1 | U41: =IF(OR(L41=0,O41=0),0,O41/L41) -> 1 | V41: =U41-T41 -> 0
A42: =A41+1 -> 180 | B42: Reinforcement Bar Fixing | D42: =E42 -> 18 | E42: =IF(AND(F42<>"",G42<>"",(G42-F42)=0),1,G42-F42+1) -> 18 | F42: 45306 | G42: 45323 | H42: =I42 -> 45330 | I42: 45330 | J42: 45351 | K42: =J42 -> 45351 | L42: 100 | M42: 0 | N42: =M42*100 -> 0 | O42: 100 | P42: % | Q42: =IF(OR(F42="",G42="",L42=""),0,MIN(MAX(IF(F42>$V$1,0,(((G42-F42)-(G42-$V$1))*(10/E42)/10)),0),1)*L42) -> 100 | S42: =D42/$D$37 -> 0.097297297 | T42: =IF(OR(L42=0,Q42=0),0,Q42/L42) -> 1 | U42: =IF(OR(L42=0,O42=0),0,O42/L42) -> 1 | V42: =U42-T42 -> 0
...

Sheet S-Curve - Overall
B54: Date | C54: 45219 | D54: =C54+7 -> 45226 | E54: =D54+7 -> 45233 | F54: =E54+7 -> 45240 | G54: =F54+7 -> 45247 | H54: =G54+7 -> 45254 | I54: =H54+7 -> 45261 | J54: =I54+7 -> 45268 | K54: =J54+7 -> 45275 | ... AI54: =AH54+7 -> 45443
B55: Work Week | C55: Week 1 | D55: Week 2 | E55: Week 3 | F55: Week 4 | G55: Week 5 | H55: Week 6 | I55: Week 7 | J55: Week 8 | K55: Week 9 | L55: Week 10 | M55: Week 11 | N55: Week 12 | O55: Week 13 | P55: Week 14 | Q55: Week 15 | R55: Week 16 | S55: Week 17 | T55: Week 18 | U55: Week 19 | V55: Week 20 | W55: Week 21 | X55: Week 22 | Y55: Week 23 | Z55: Week 24 | AA55: Week 25 | AB55: Week 26 | AC55: Week 27 | AD55: Week 28 | AE55: Week 29 | AF55: Week 30 | AG55: Week 31 | AH55: Week 32 | AI55: Week 33
B56: Plan | C56: =C58 -> 0 | D56: =D58-C58 -> 0 | E56: =E58-D58 -> 0 | F56: =F58-E58 -> 0 | G56: =G58-F58 -> 0 | H56: =H58-G58 -> 0 | I56: =I58-H58 -> 0.00017774618 | J56: =J58-I58 -> 0.003021685 | K56: =K58-J58 -> 0.011553502 | ... AI56: =AI58-AH58 -> 0
B57: Actual | C57: 0 | D57: =D59-C59 -> 0 | E57: =E59-D59 -> 0 | F57: =F59-E59 -> 0 | G57: =G59-F59 -> 0 | H57: =H59-G59 -> 0 | I57: =I59-H59 -> 0 | J57: =J59-I59 -> 0.0035 | K57: =K59-J59 -> 0.01 | ... AI57: =AI59-AH59 -> 0
B58: Plan Cum | C58: =HLOOKUP(C54,'Curve Data'!T:BS,8,FALSE) -> 0 | D58: =HLOOKUP(D54,'Curve Data'!U:BT,8,FALSE) -> 0 | E58: =HLOOKUP(E54,'Curve Data'!V:BU,8,FALSE) -> 0 | F58: =HLOOKUP(F54,'Curve Data'!W:BV,8,FALSE) -> 0 | G58: =HLOOKUP(G54,'Curve Data'!X:BW,8,FALSE) -> 0 | H58: =HLOOKUP(H54,'Curve Data'!Y:BX,8,FALSE) -> 0 | I58: =HLOOKUP(I54,'Curve Data'!Z:BY,8,FALSE) -> 0.00017774618 | J58: =HLOOKUP(J54,'Curve Data'!AA:BZ,8,FALSE) -> 0.0031994312 | K58: =HLOOKUP(K54,'Curve Data'!AB:CA,8,FALSE) -> 0.014752933 | L58: =HLOOKUP(L54,'Curve Data'!AC:CB,8,FALSE) -> 0.042836829 | M58: =HLOOKUP(M54,'Curve Data'!AD:CC,8,FALSE) -> 0.10620334 | N58: =HLOOKUP(N54,'Curve Data'!AE:CD,8,FALSE) -> 0.20600782 | O58: =HLOOKUP(O54,'Curve Data'!AF:CE,8,FALSE) -> 0.34091717 | P58: =HLOOKUP(P54,'Curve Data'!AG:CF,8,FALSE) -> 0.49777817 | Q58: =HLOOKUP(Q54,'Curve Data'!AH:CG,8,FALSE) -> 0.6591717 | R58: =HLOOKUP(R54,'Curve Data'!AI:CH,8,FALSE) -> 0.79674724 | S58: =HLOOKUP(S54,'Curve Data'!AJ:CI,8,FALSE) -> 0.89912904 | T58: =HLOOKUP(T54,'Curve Data'!AK:CJ,8,FALSE) -> 0.959385 | U58: =HLOOKUP(U54,'Curve Data'!AL:CK,8,FALSE) -> 0.98853537 | V58: =HLOOKUP(V54,'Curve Data'!AM:CL,8,FALSE) -> 1 | W58: =HLOOKUP(W54,'Curve Data'!AN:CM,8,FALSE) -> 1 | X58: =HLOOKUP(X54,'Curve Data'!AO:CN,8,FALSE) -> 1 | Y58: =HLOOKUP(Y54,'Curve Data'!AP:CO,8,FALSE) -> 1 | Z58: =HLOOKUP(Z54,'Curve Data'!AQ:CP,8,FALSE) -> 1 | AA58: =HLOOKUP(AA54,'Curve Data'!AR:CQ,8,FALSE) -> 1 | AB58: =HLOOKUP(AB54,'Curve Data'!AS:CR,8,FALSE) -> 1 | AC58: =HLOOKUP(AC54,'Curve Data'!AT:CS,8,FALSE) -> 1 | AD58: =HLOOKUP(AD54,'Curve Data'!AU:CT,8,FALSE) -> 1 | AE58: =HLOOKUP(AE54,'Curve Data'!AV:CU,8,FALSE) -> 1 | AF58: =HLOOKUP(AF54,'Curve Data'!AW:CV,8,FALSE) -> 1 | AG58: =HLOOKUP(AG54,'Curve Data'!AX:CW,8,FALSE) -> 1 | AH58: =HLOOKUP(AH54,'Curve Data'!AY:CX,8,FALSE) -> 1 | AI58: =HLOOKUP(AI54,'Curve Data'!AZ:CY,8,FALSE) -> 1
B59: Actual Cum | C59: 0 | D59: 0 | E59: 0 | F59: 0 | G59: 0 | H59: 0 | I59: 0 | J59: 0.0035 | K59: 0.0135 | L59: 0.060740797 | M59: 0.094975893 | N59: 0.12337185 | O59: 0.16871508 | P59: 0.23119056 | Q59: 0.27764144 | R59: 0.34438997 | S59: 0.40114196 | T59: 0.46327749 | U59: 0.53315424 | V59: 0.58452304 | W59: 0.64044788 | X59: 0.68331308 | Y59: 0.74311258 | Z59: 0.78551341 | AA59: 0.81371409 | AB59: 0.83225962 | AC59: 0.84184391 | AD59: 0.85928546 | AE59: 0.87690654 | AF59: 0.9125713
B60: Variance | C60: =C59-C58 -> 0 | D60: =D59-D58 -> 0 | E60: =E59-E58 -> 0 | F60: =F59-F58 -> 0 | G60: =G59-G58 -> 0 | H60: =H59-H58 -> 0 | I60: =I59-I58 -> -0.00017774618 | J60: =J59-J58 -> 0.00030056879 | ... AI60: =AI59-AI58 -> -1

Sheet Resource Loading
C57: 45219 | D57: =C57+7 -> 45226 | E57: =D57+7 -> 45233 | F57: =E57+7 -> 45240 | G57: =F57+7 -> 45247 | H57: =G57+7 -> 45254 | I57: =H57+7 -> 45261 | J57: =I57+7 -> 45268 | K57: =J57+7 -> 45275 | ... AF57: =AE57+7 -> 45422
C58: Week 1 | D58: Week 2 | E58: Week 3 | F58: Week 4 | G58: Week 5 | H58: Week 6 | I58: Week 7 | J58: Week 8 | K58: Week 9 | L58: Week 10 | M58: Week 11 | N58: Week 12 | O58: Week 13 | P58: Week 14 | Q58: Week 15 | R58: Week 16 | S58: Week 17 | T58: Week 18 | U58: Week 19 | V58: Week 20 | W58: Week 21 | X58: Week 22 | Y58: Week 23 | Z58: Week 24 | AA58: Week 25 | AB58: Week 26 | AC58: Week 27 | AD58: Week 28 | AE58: Week 29 | AF58: Week 30
B59: P - Site | C59: 0 | D59: 0 | E59: 0 | F59: 0 | G59: 20 | H59: 79 | I59: 75 | J59: 77 | K59: 117 | L59: 149 | M59: 195 | N59: 195 | O59: 195 | P59: 195 | Q59: 195 | R59: 195 | S59: 195 | T59: 195 | U59: 195 | V59: 65
B60: P - W/S | C60: 0 | D60: 0 | E60: 0 | F60: 0 | G60: 10 | H60: 15 | I60: 30 | J60: 35 | K60: 33 | L60: 61 | M60: 69 | N60: 69 | O60: 69 | P60: 69 | Q60: 69 | R60: 69 | S60: 69 | T60: 69 | U60: 69 | V60: 0
B61: Plan | C61: =SUM(C59:C60) -> 0 | D61: =SUM(D59:D60) -> 0 | E61: =SUM(E59:E60) -> 0 | F61: =SUM(F59:F60) -> 0 | G61: =SUM(G59:G60) -> 30 | H61: =SUM(H59:H60) -> 94 | I61: =SUM(I59:I60) -> 105 | J61: =SUM(J59:J60) -> 112 | ... AF61: =SUM(AF59:AF60) -> 0
B62: A - Site | C62: 0 | D62: 0 | E62: 0 | F62: 0 | G62: 23 | H62: 18 | I62: 45 | J62: 85 | K62: 122 | L62: =122+30 -> 152 | M62: =134+40 -> 174 | N62: 184 | O62: =295-33+30 -> 292 | P62: =252+1+11+30 -> 294 | Q62: =279+1+11+30 -> 321 | R62: 321 | S62: 361 | T62: 361 | U62: 376 | V62: 376 | W62: =295+27 -> 322 | X62: =280+23 -> 303 | Y62: =278+12+22 -> 312 | Z62: 265 | AA62: 265 | AB62: 240 | AC62: 205 | AD62: 205 | AE62: 198 | AF62: 198
B63: A - W/S | C63: 0 | D63: 0 | E63: 0 | F63: 0 | G63: 10 | H63: 15 | I63: 30 | J63: 30 | K63: 33 | L63: 45 | M63: 52 | N63: 52 | O63: 33 | P63: 35 | Q63: 39 | R63: 39 | S63: 39 | T63: 39 | U63: 39 | V63: 39 | W63: 39 | X63: 0 | Y63: 0 | Z63: 0 | AA63: 0 | AB63: 0 | AC63: 0 | AD63: 0 | AE63: 0 | AF63: 0
B64: Actual | C64: =SUM(C62:C63) -> 0 | D64: =SUM(D62:D63) -> 0 | E64: =SUM(E62:E63) -> 0 | F64: =SUM(F62:F63) -> 0 | G64: =SUM(G62:G63) -> 33 | H64: =SUM(H62:H63) -> 33 | I64: =SUM(I62:I63) -> 75 | J64: =SUM(J62:J63) -> 115 | ... AF64: =SUM(AF62:AF63) -> 198
B65: Management | C65: 0 | D65: 0 | E65: 0 | F65: 5 | G65: 8 | H65: 12 | I65: 15 | J65: 18 | K65: 21 | L65: 26 | M65: 26 | N65: 26 | O65: 26 | P65: 26 | Q65: 26 | R65: 26 | S65: 26 | T65: 26 | U65: 26 | V65: 26 | W65: 26 | X65: 26 | Y65: 26 | Z65: 26 | AA65: 24 | AB65: 24 | AC65: 24 | AD65: 24 | AE65: 24 | AF65: 22

Sheet Curve Data
B1: =Overall!B1 -> PROJECT : ECOCERES SUBSTRUCTURE WORKS | N1: Updated On : | O1: 45366 | U1: 45219 | W1: =U1+7 -> 45226 | Y1: =W1+7 -> 45233 | AA1: =Y1+7 -> 45240 | AC1: =AA1+7 -> 45247 | AE1: =AC1+7 -> 45254 | AG1: =AE1+7 -> 45261 | AI1: =AG1+7 -> 45268 | AK1: =AI1+7 -> 45275 | AM1: =AK1+7 -> 45282 | AO1: =AM1+7 -> 45289 | AQ1: =AO1+7 -> 45296 | AS1: =AQ1+7 -> 45303 | AU1: =AS1+7 -> 45310 | AW1: =AU1+7 -> 45317 | AY1: =AW1+7 -> 45324 | BA1: =AY1+7 -> 45331 | BC1: =BA1+7 -> 45338 | BE1: =BC1+7 -> 45345 | BG1: =BE1+7 -> 45352 | BI1: =BG1+7 -> 45359 | BK1: =BI1+7 -> 45366 | BM1: =BK1+7 -> 45373 | BO1: =BM1+7 -> 45380 | BQ1: =BO1+7 -> 45387 | BS1: =BQ1+7 -> 45394 | BU1: =BS1+7 -> 45401 | BW1: =BU1+7 -> 45408 | BY1: =BW1+7 -> 45415 | CA1: =BY1+7 -> 45422 | CC1: =CA1+7 -> 45429 | CE1: =CC1+7 -> 45436 | CG1: =CE1+7 -> 45443 | CI1: =CG1+7 -> 45450 | CK1: =CI1+7 -> 45457 | CM1: =CK1+7 -> 45464
B2: WEEKLY SCHEDULE & PROGRESS UPDATE
B4: CONTRACTOR | C4: PACKAGE NO | F4: Plan Start | G4: Plan Finish
B5: DYNACIATE | C5: ECOCERES SUBSTRUCTURE PACKAGE | F5: =F8 -> 45259 | G5: =G8 -> 45350
B7: Activity ID | C7: Activity Description | D7: Sub sum | E7: Plan Duration | F7: Baseline Start | G7: Baseline Finish | H7: Total Quantity | I7: Installed Quantity | J7: Unit | K7: Plan Units | L7: Weightage | M7: Plan Prog % | N7: Actual Prog % | O7: Delta | P7: Remark | T7: Plan Units | U7: Plan Prog % | V7: Plan Units | W7: Plan Prog % | X7: Plan Units | Y7: Plan Prog % | Z7: Plan Units | AA7: Plan Prog % | AB7: Plan Units | AC7: Plan Prog % | AD7: Plan Units | AE7: Plan Prog % | AF7: Plan Units | AG7: Plan Prog % | AH7: Plan Units | AI7: Plan Prog % | AJ7: Plan Units | AK7: Plan Prog % | AL7: Plan Units | AM7: Plan Prog % | AN7: Plan Units | AO7: Plan Prog % | AP7: Plan Units | AQ7: Plan Prog % | AR7: Plan Units | AS7: Plan Prog % | AT7: Plan Units | AU7: Plan Prog % | AV7: Plan Units | AW7: Plan Prog % | AX7: Plan Units | AY7: Plan Prog % | AZ7: Plan Units | BA7: Plan Prog % | BB7: Plan Units | BC7: Plan Prog % | BD7: Plan Units | BE7: Plan Prog % | BF7: Plan Units | BG7: Plan Prog % | BH7: Plan Units | BI7: Plan Prog % | BJ7: Plan Units | BK7: Plan Prog % | BL7: Plan Units | BM7: Plan Prog % | BN7: Plan Units | BO7: Plan Prog % | BP7: Plan Units | BQ7: Plan Prog % | BR7: Plan Units | BS7: Plan Prog % | BT7: Plan Units | BU7: Plan Prog % | BV7: Plan Units | BW7: Plan Prog % | BX7: Plan Units | BY7: Plan Prog % | BZ7: Plan Units | CA7: Plan Prog % | CB7: Plan Units | CC7: Plan Prog % | CD7: Plan Units | CE7: Plan Prog % | CF7: Plan Units | CG7: Plan Prog % | CH7: Plan Units | CI7: Plan Prog % | CJ7: Plan Units | CK7: Plan Prog % | CL7: Plan Units | CM7: Plan Prog %
A8: 0.1 | B8: PELICAN S01B SITE ESTABLISHMENT | D8: 11252 | E8: 92 | F8: =MIN(F9:F1037) -> 45259 | G8: =MAX(G9:G1037) -> 45350 | L8: =SUM(L9,L592,L1036) -> 1 | M8: =$L9*M9+$L592*M592+$L1036*M1036 -> 1 | N8: =$L9*N9+$L592*N592+$L1036*N1036 -> 1 | O8: =N8-M8 -> 0 | U8: =$L9*U9+$L592*U592+$L1036*U1036 -> 0 | W8: =$L9*W9+$L592*W592+$L1036*W1036 -> 0 | Y8: =$L9*Y9+$L592*Y592+$L1036*Y1036 -> 0 | AA8: =$L9*AA9+$L592*AA592+$L1036*AA1036 -> 0 | AC8: =$L9*AC9+$L592*AC592+$L1036*AC1036 -> 0 | AE8: =$L9*AE9+$L592*AE592+$L1036*AE1036 -> 0 | AG8: =$L9*AG9+$L592*AG592+$L1036*AG1036 -> 0.00017774618 | AI8: =$L9*AI9+$L592*AI592+$L1036*AI1036 -> 0.0031994312 | AK8: =$L9*AK9+$L592*AK592+$L1036*AK1036 -> 0.014752933 | AM8: =$L9*AM9+$L592*AM592+$L1036*AM1036 -> 0.042836829 | AO8: =$L9*AO9+$L592*AO592+$L1036*AO1036 -> 0.10620334 | AQ8: =$L9*AQ9+$L592*AQ592+$L1036*AQ1036 -> 0.20600782 | AS8: =$L9*AS9+$L592*AS592+$L1036*AS1036 -> 0.34091717 | AU8: =$L9*AU9+$L592*AU592+$L1036*AU1036 -> 0.49777817 | AW8: =$L9*AW9+$L592*AW592+$L1036*AW1036 -> 0.6591717 | AY8: =$L9*AY9+$L592*AY592+$L1036*AY1036 -> 0.79674724 | BA8: =$L9*BA9+$L592*BA592+$L1036*BA1036 -> 0.89912904 | BC8: =$L9*BC9+$L592*BC592+$L1036*BC1036 -> 0.959385 | BE8: =$L9*BE9+$L592*BE592+$L1036*BE1036 -> 0.98853537 | BG8: =$L9*BG9+$L592*BG592+$L1036*BG1036 -> 1 | BI8: =$L9*BI9+$L592*BI592+$L1036*BI1036 -> 1 | BK8: =$L9*BK9+$L592*BK592+$L1036*BK1036 -> 1 | BM8: =$L9*BM9+$L592*BM592+$L1036*BM1036 -> 1 | BO8: =$L9*BO9+$L592*BO592+$L1036*BO1036 -> 1 | BQ8: =$L9*BQ9+$L592*BQ592+$L1036*BQ1036 -> 1 | BS8: =$L9*BS9+$L592*BS592+$L1036*BS1036 -> 1 | BU8: =$L9*BU9+$L592*BU592+$L1036*BU1036 -> 1 | BW8: =$L9*BW9+$L592*BW592+$L1036*BW1036 -> 1 | BY8: =$L9*BY9+$L592*BY592+$L1036*BY1036 -> 1 | CA8: =$L9*CA9+$L592*CA592+$L1036*CA1036 -> 1 | CC8: =$L9*CC9+$L592*CC592+$L1036*CC1036 -> 1 | CE8: =$L9*CE9+$L592*CE592+$L1036*CE1036 -> 1 | CG8: =$L9*CG9+$L592*CG592+$L1036*CG1036 -> 1 | CI8: =$L9*CI9+$L592*CI592+$L1036*CI1036 -> 1 | CK8: =$L9*CK9+$L592*CK592+$L1036*CK1036 -> 1 | CM8: =$L9*CM9+$L592*CM592+$L1036*CM1036 -> 1
A9: =Overall!A9 -> 147 | B9: UNIT 700, 800 and 900 (SUBSTRUCTURE) | D9: 8781 | E9: 92 | F9: 45259 | G9: 45350 | L9: =D9/$D$8 -> 0.7803946 | M9: =$L10*M10+$L83*M83+$L136*M136+$L211*M211+$L263*M263+$L315*M315+$L383*M383+$L435*M435+$L487*M487+$L539*M539+$L591*M591 -> 1 | N9: =$L10*N10+$L83*N83+$L136*N136+$L211*N211+$L263*N263+$L315*N315+$L383*N383+$L435*N435+$L487*N487+$L539*N539+$L591*N591 -> 1 | O9: =N9-M9 -> 0 | U9: =$L10*U10+$L83*U83+$L136*U136+$L211*U211+$L263*U263+$L315*U315+$L383*U383+$L435*U435+$L487*U487+$L539*U539+$L591*U591 -> 0 | W9: =$L10*W10+$L83*W83+$L136*W136+$L211*W211+$L263*W263+$L315*W315+$L383*W383+$L435*W435+$L487*W487+$L539*W539+$L591*W591 -> 0 | Y9: =$L10*Y10+$L83*Y83+$L136*Y136+$L211*Y211+$L263*Y263+$L315*Y315+$L383*Y383+$L435*Y435+$L487*Y487+$L539*Y539+$L591*Y591 -> 0 | AA9: =$L10*AA10+$L83*AA83+$L136*AA136+$L211*AA211+$L263*AA263+$L315*AA315+$L383*AA383+$L435*AA435+$L487*AA487+$L539*AA539+$L591*AA591 -> 0 | AC9: =$L10*AC10+$L83*AC83+$L136*AC136+$L211*AC211+$L263*AC263+$L315*AC315+$L383*AC383+$L435*AC435+$L487*AC487+$L539*AC539+$L591*AC591 -> 0 | AE9: =$L10*AE10+$L83*AE83+$L136*AE136+$L211*AE211+$L263*AE263+$L315*AE315+$L383*AE383+$L435*AE435+$L487*AE487+$L539*AE539+$L591*AE591 -> 0 | AG9: =$L10*AG10+$L83*AG83+$L136*AG136+$L211*AG211+$L263*AG263+$L315*AG315+$L383*AG383+$L435*AG435+$L487*AG487+$L539*AG539+$L591*AG591 -> 0.00022776449 | AI9: =$L10*AI10+$L83*AI83+$L136*AI136+$L211*AI211+$L263*AI263+$L315*AI315+$L383*AI383+$L435*AI435+$L487*AI487+$L539*AI539+$L591*AI591 -> 0.0040997608 | AK9: =$L10*AK10+$L83*AK83+$L136*AK136+$L211*AK211+$L263*AK263+$L315*AK315+$L383*AK383+$L435*AK435+$L487*AK487+$L539*AK539+$L591*AK591 -> 0.017993395 | AM9: =$L10*AM10+$L83*AM83+$L136*AM136+$L211*AM211+$L263*AM263+$L315*AM315+$L383*AM383+$L435*AM435+$L487*AM487+$L539*AM539+$L591*AM591 -> 0.050335953 | AO9: =$L10*AO10+$L83*AO83+$L136*AO136+$L211*AO211+$L263*AO263+$L315*AO315+$L383*AO383+$L435*AO435+$L487*AO487+$L539*AO539+$L591*AO591 -> 0.12048742 | AQ9: =$L10*AQ10+$L83*AQ83+$L136*AQ136+$L211*AQ211+$L263*AQ263+$L315*AQ315+$L383*AQ383+$L435*AQ435+$L487*AQ487+$L539*AQ539+$L591*AQ591 -> 0.22822002 | AS9: =$L10*AS10+$L83*AS83+$L136*AS136+$L211*AS211+$L263*AS263+$L315*AS315+$L383*AS383+$L435*AS435+$L487*AS487+$L539*AS539+$L591*AS591 -> 0.36670083 | AU9: =$L10*AU10+$L83*AU83+$L136*AU136+$L211*AU211+$L263*AU263+$L315*AU315+$L383*AU383+$L435*AU435+$L487*AU487+$L539*AU539+$L591*AU591 -> 0.5234028 | AW9: =$L10*AW10+$L83*AW83+$L136*AW136+$L211*AW211+$L263*AW263+$L315*AW315+$L383*AW383+$L435*AW435+$L487*AW487+$L539*AW539+$L591*AW591 -> 0.67623278 | AY9: =$L10*AY10+$L83*AY83+$L136*AY136+$L211*AY211+$L263*AY263+$L315*AY315+$L383*AY383+$L435*AY435+$L487*AY487+$L539*AY539+$L591*AY591 -> 0.80742512 | BA9: =$L10*BA10+$L83*BA83+$L136*BA136+$L211*BA211+$L263*BA263+$L315*BA315+$L383*BA383+$L435*BA435+$L487*BA487+$L539*BA539+$L591*BA591 -> 0.90411115 | BC9: =$L10*BC10+$L83*BC83+$L136*BC136+$L211*BC211+$L263*BC263+$L315*BC315+$L383*BC383+$L435*BC435+$L487*BC487+$L539*BC539+$L591*BC591 -> 0.96105227 | BE9: =$L10*BE10+$L83*BE83+$L136*BE136+$L211*BE211+$L263*BE263+$L315*BE315+$L383*BE383+$L435*BE435+$L487*BE487+$L539*BE539+$L591*BE591 -> 0.9890673 | BG9: =$L10*BG10+$L83*BG83+$L136*BG136+$L211*BG211+$L263*BG263+$L315*BG315+$L383*BG383+$L435*BG435+$L487*BG487+$L539*BG539+$L591*BG591 -> 1 | BI9: =$L10*BI10+$L83*BI83+$L136*BI136+$L211*BI211+$L263*BI263+$L315*BI315+$L383*BI383+$L435*BI435+$L487*BI487+$L539*BI539+$L591*BI591 -> 1 | BK9: =$L10*BK10+$L83*BK83+$L136*BK136+$L211*BK211+$L263*BK263+$L315*BK315+$L383*BK383+$L435*BK435+$L487*BK487+$L539*BK539+$L591*BK591 -> 1 | BM9: =$L10*BM10+$L83*BM83+$L136*BM136+$L211*BM211+$L263*BM263+$L315*BM315+$L383*BM383+$L435*BM435+$L487*BM487+$L539*BM539+$L591*BM591 -> 1 | BO9: =$L10*BO10+$L83*BO83+$L136*BO136+$L211*BO211+$L263*BO263+$L315*BO315+$L383*BO383+$L435*BO435+$L487*BO487+$L539*BO539+$L591*BO591 -> 1 | BQ9: =$L10*BQ10+$L83*BQ83+$L136*BQ136+$L211*BQ211+$L263*BQ263+$L315*BQ315+$L383*BQ383+$L435*BQ435+$L487*BQ487+$L539*BQ539+$L591*BQ591 -> 1 | BS9: =$L10*BS10+$L83*BS83+$L136*BS136+$L211*BS211+$L263*BS263+$L315*BS315+$L383*BS383+$L435*BS435+$L487*BS487+$L539*BS539+$L591*BS591 -> 1 | BU9: =$L10*BU10+$L83*BU83+$L136*BU136+$L211*BU211+$L263*BU263+$L315*BU315+$L383*BU383+$L435*BU435+$L487*BU487+$L539*BU539+$L591*BU591 -> 1 | BW9: =$L10*BW10+$L83*BW83+$L136*BW136+$L211*BW211+$L263*BW263+$L315*BW315+$L383*BW383+$L435*BW435+$L487*BW487+$L539*BW539+$L591*BW591 -> 1 | BY9: =$L10*BY10+$L83*BY83+$L136*BY136+$L211*BY211+$L263*BY263+$L315*BY315+$L383*BY383+$L435*BY435+$L487*BY487+$L539*BY539+$L591*BY591 -> 1 | CA9: =$L10*CA10+$L83*CA83+$L136*CA136+$L211*CA211+$L263*CA263+$L315*CA315+$L383*CA383+$L435*CA435+$L487*CA487+$L539*CA539+$L591*CA591 -> 1 | CC9: =$L10*CC10+$L83*CC83+$L136*CC136+$L211*CC211+$L263*CC263+$L315*CC315+$L383*CC383+$L435*CC435+$L487*CC487+$L539*CC539+$L591*CC591 -> 1 | CE9: =$L10*CE10+$L83*CE83+$L136*CE136+$L211*CE211+$L263*CE263+$L315*CE315+$L383*CE383+$L435*CE435+$L487*CE487+$L539*CE539+$L591*CE591 -> 1 | CG9: =$L10*CG10+$L83*CG83+$L136*CG136+$L211*CG211+$L263*CG263+$L315*CG315+$L383*CG383+$L435*CG435+$L487*CG487+$L539*CG539+$L591*CG591 -> 1 | CI9: =$L10*CI10+$L83*CI83+$L136*CI136+$L211*CI211+$L263*CI263+$L315*CI315+$L383*CI383+$L435*CI435+$L487*CI487+$L539*CI539+$L591*CI591 -> 1 | CK9: =$L10*CK10+$L83*CK83+$L136*CK136+$L211*CK211+$L263*CK263+$L315*CK315+$L383*CK383+$L435*CK435+$L487*CK487+$L539*CK539+$L591*CK591 -> 1 | CM9: =$L10*CM10+$L83*CM83+$L136*CM136+$L211*CM211+$L263*CM263+$L315*CM315+$L383*CM383+$L435*CM435+$L487*CM487+$L539*CM539+$L591*CM591 -> 1
A10: =A9+1 -> 148 | B10: Unit 700 - Auxillary & Tank Yard | D10: 819 | E10: 73 | F10: 45265 | G10: 45337 | L10: =D10/$D$9 -> 0.093269559 | M10: =$L11*M11+$L14*M14+$L82*M82 -> 1 | N10: =$L11*N11+$L14*N14+$L82*N82 -> 1 | O10: =N10-M10 -> 0 | U10: =$L11*U11+$L14*U14+$L82*U82 -> 0 | W10: =$L11*W11+$L14*W14+$L82*W82 -> 0 | Y10: =$L11*Y11+$L14*Y14+$L82*Y82 -> 0 | AA10: =$L11*AA11+$L14*AA14+$L82*AA82 -> 0 | AC10: =$L11*AC11+$L14*AC14+$L82*AC82 -> 0 | AE10: =$L11*AE11+$L14*AE14+$L82*AE82 -> 0 | AG10: =$L11*AG11+$L14*AG14+$L82*AG82 -> 0 | AI10: =$L11*AI11+$L14*AI14+$L82*AI82 -> 0.0036630037 | AK10: =$L11*AK11+$L14*AK14+$L82*AK82 -> 0.0085470085 | AM10: =$L11*AM11+$L14*AM14+$L82*AM82 -> 0.024420024 | AO10: =$L11*AO11+$L14*AO14+$L82*AO82 -> 0.09035409 | AQ10: =$L11*AQ11+$L14*AQ14+$L82*AQ82 -> 0.1953602 | AS10: =$L11*AS11+$L14*AS14+$L82*AS82 -> 0.35164835 | AU10: =$L11*AU11+$L14*AU14+$L82*AU82 -> 0.53113553 | AW10: =$L11*AW11+$L14*AW14+$L82*AW82 -> 0.72771673 | AY10: =$L11*AY11+$L14*AY14+$L82*AY82 -> 0.87423687 | BA10: =$L11*BA11+$L14*BA14+$L82*BA82 -> 0.96336996 | BC10: =$L11*BC11+$L14*BC14+$L82*BC82 -> 1 | BE10: =$L11*BE11+$L14*BE14+$L82*BE82 -> 1 | BG10: =$L11*BG11+$L14*BG14+$L82*BG82 -> 1 | BI10: =$L11*BI11+$L14*BI14+$L82*BI82 -> 1 | BK10: =$L11*BK11+$L14*BK14+$L82*BK82 -> 1 | BM10: =$L11*BM11+$L14*BM14+$L82*BM82 -> 1 | BO10: =$L11*BO11+$L14*BO14+$L82*BO82 -> 1 | BQ10: =$L11*BQ11+$L14*BQ14+$L82*BQ82 -> 1 | BS10: =$L11*BS11+$L14*BS14+$L82*BS82 -> 1 | BU10: =$L11*BU11+$L14*BU14+$L82*BU82 -> 1 | BW10: =$L11*BW11+$L14*BW14+$L82*BW82 -> 1 | BY10: =$L11*BY11+$L14*BY14+$L82*BY82 -> 1 | CA10: =$L11*CA11+$L14*CA14+$L82*CA82 -> 1 | CC10: =$L11*CC11+$L14*CC14+$L82*CC82 -> 1 | CE10: =$L11*CE11+$L14*CE14+$L82*CE82 -> 1 | CG10: =$L11*CG11+$L14*CG14+$L82*CG82 -> 1 | CI10: =$L11*CI11+$L14*CI14+$L82*CI82 -> 1 | CK10: =$L11*CK11+$L14*CK14+$L82*CK82 -> 1 | CM10: =$L11*CM11+$L14*CM14+$L82*CM82 -> 1
A11: =A10+1 -> 149 | B11: Piling (Cutting only) | D11: 7 | E11: 7 | F11: 45265 | G11: 45271 | L11: =D11/$D$10 -> 0.0085470085 | M11: {=SUMPRODUCT($L12:$L13*M12:M13)} -> 1 | N11: {=SUMPRODUCT($L12:$L13*N12:N13)} -> 1 | O11: =N11-M11 -> 0 | U11: {=SUMPRODUCT($L12:$L13*U12:U13)} -> 0 | W11: {=SUMPRODUCT($L12:$L13*W12:W13)} -> 0 | Y11: {=SUMPRODUCT($L12:$L13*Y12:Y13)} -> 0 | AA11: {=SUMPRODUCT($L12:$L13*AA12:AA13)} -> 0 | AC11: {=SUMPRODUCT($L12:$L13*AC12:AC13)} -> 0 | AE11: {=SUMPRODUCT($L12:$L13*AE12:AE13)} -> 0 | AG11: {=SUMPRODUCT($L12:$L13*AG12:AG13)} -> 0 | AI11: {=SUMPRODUCT($L12:$L13*AI12:AI13)} -> 0.42857143 | AK11: {=SUMPRODUCT($L12:$L13*AK12:AK13)} -> 1 | AM11: {=SUMPRODUCT($L12:$L13*AM12:AM13)} -> 1 | AO11: {=SUMPRODUCT($L12:$L13*AO12:AO13)} -> 1 | AQ11: {=SUMPRODUCT($L12:$L13*AQ12:AQ13)} -> 1 | AS11: {=SUMPRODUCT($L12:$L13*AS12:AS13)} -> 1 | AU11: {=SUMPRODUCT($L12:$L13*AU12:AU13)} -> 1 | AW11: {=SUMPRODUCT($L12:$L13*AW12:AW13)} -> 1 | AY11: {=SUMPRODUCT($L12:$L13*AY12:AY13)} -> 1 | BA11: {=SUMPRODUCT($L12:$L13*BA12:BA13)} -> 1 | BC11: {=SUMPRODUCT($L12:$L13*BC12:BC13)} -> 1 | BE11: {=SUMPRODUCT($L12:$L13*BE12:BE13)} -> 1 | BG11: {=SUMPRODUCT($L12:$L13*BG12:BG13)} -> 1 | BI11: {=SUMPRODUCT($L12:$L13*BI12:BI13)} -> 1 | BK11: {=SUMPRODUCT($L12:$L13*BK12:BK13)} -> 1 | BM11: {=SUMPRODUCT($L12:$L13*BM12:BM13)} -> 1 | BO11: {=SUMPRODUCT($L12:$L13*BO12:BO13)} -> 1 | BQ11: {=SUMPRODUCT($L12:$L13*BQ12:BQ13)} -> 1 | BS11: {=SUMPRODUCT($L12:$L13*BS12:BS13)} -> 1 | BU11: {=SUMPRODUCT($L12:$L13*BU12:BU13)} -> 1 | BW11: {=SUMPRODUCT($L12:$L13*BW12:BW13)} -> 1 | BY11: {=SUMPRODUCT($L12:$L13*BY12:BY13)} -> 1 | CA11: {=SUMPRODUCT($L12:$L13*CA12:CA13)} -> 1 | CC11: {=SUMPRODUCT($L12:$L13*CC12:CC13)} -> 1 | CE11: {=SUMPRODUCT($L12:$L13*CE12:CE13)} -> 1 | CG11: {=SUMPRODUCT($L12:$L13*CG12:CG13)} -> 1 | CI11: {=SUMPRODUCT($L12:$L13*CI12:CI13)} -> 1 | CK11: {=SUMPRODUCT($L12:$L13*CK12:CK13)} -> 1 | CM11: {=SUMPRODUCT($L12:$L13*CM12:CM13)} -> 1
A12: =A11+1 -> 150 | B12: Cutting off Pile to GL | D12: 7 | E12: 7 | F12: 45265 | G12: 45271 | H12: 100 | I12: 100 | J12: % | K12: =IF(OR(F12="",G12="",H12=""),0,MIN(MAX(IF(F12>$O$1,0,(((G12-F12)-(G12-$O$1))*(10/E12)/10)),0),1)*H12) -> 100 | L12: =D12/$D$11 -> 1 | M12: =IF(OR(H12=0,K12=0),0,K12/H12) -> 1 | N12: =IF(OR(H12=0,I12=0),0,I12/H12) -> 1 | O12: =N12-M12 -> 0 | T12: =IF(OR($F12="",$G12="",$H12=""),0,MIN(MAX(IF($F12>U$1,0,((($G12-$F12)-($G12-U$1))*(10/$E12)/10)),0),1)*$H12) -> 0 | U12: =IF(OR($H12=0,T12=0),0,T12/$H12) -> 0 | V12: =IF(OR($F12="",$G12="",$H12=""),0,MIN(MAX(IF($F12>W$1,0,((($G12-$F12)-($G12-W$1))*(10/$E12)/10)),0),1)*$H12) -> 0 | W12: =IF(OR($H12=0,V12=0),0,V12/$H12) -> 0 | X12: =IF(OR($F12="",$G12="",$H12=""),0,MIN(MAX(IF($F12>Y$1,0,((($G12-$F12)-($G12-Y$1))*(10/$E12)/10)),0),1)*$H12) -> 0 | Y12: =IF(OR($H12=0,X12=0),0,X12/$H12) -> 0 | Z12: =IF(OR($F12="",$G12="",$H12=""),0,MIN(MAX(IF($F12>AA$1,0,((($G12-$F12)-($G12-AA$1))*(10/$E12)/10)),0),1)*$H12) -> 0 | AA12: =IF(OR($H12=0,Z12=0),0,Z12/$H12) -> 0 | AB12: =IF(OR($F12="",$G12="",$H12=""),0,MIN(MAX(IF($F12>AC$1,0,((($G12-$F12)-($G12-AC$1))*(10/$E12)/10)),0),1)*$H12) -> 0 | AC12: =IF(OR($H12=0,AB12=0),0,AB12/$H12) -> 0 | AD12: =IF(OR($F12="",$G12="",$H12=""),0,MIN(MAX(IF($F12>AE$1,0,((($G12-$F12)-($G12-AE$1))*(10/$E12)/10)),0),1)*$H12) -> 0 | AE12: =IF(OR($H12=0,AD12=0),0,AD12/$H12) -> 0 | AF12: =IF(OR($F12="",$G12="",$H12=""),0,MIN(MAX(IF($F12>AG$1,0,((($G12-$F12)-($G12-AG$1))*(10/$E12)/10)),0),1)*$H12) -> 0 | AG12: =IF(OR($H12=0,AF12=0),0,AF12/$H12) -> 0 | AH12: =IF(OR($F12="",$G12="",$H12=""),0,MIN(MAX(IF($F12>AI$1,0,((($G12-$F12)-($G12-AI$1))*(10/$E12)/10)),0),1)*$H12) -> 42.857143 | AI12: =IF(OR($H12=0,AH12=0),0,AH12/$H12) -> 0.42857143 | AJ12: =IF(OR($F12="",$G12="",$H12=""),0,MIN(MAX(IF($F12>AK$1,0,((($G12-$F12)-($G12-AK$1))*(10/$E12)/10)),0),1)*$H12) -> 100 | AK12: =IF(OR($H12=0,AJ12=0),0,AJ12/$H12) -> 1 | AL12: =IF(OR($F12="",$G12="",$H12=""),0,MIN(MAX(IF($F12>AM$1,0,((($G12-$F12)-($G12-AM$1))*(10/$E12)/10)),0),1)*$H12) -> 100 | AM12: =IF(OR($H12=0,AL12=0),0,AL12/$H12) -> 1 | AN12: =IF(OR($F12="",$G12="",$H12=""),0,MIN(MAX(IF($F12>AO$1,0,((($G12-$F12)-($G12-AO$1))*(10/$E12)/10)),0),1)*$H12) -> 100 | AO12: =IF(OR($H12=0,AN12=0),0,AN12/$H12) -> 1 | AP12: =IF(OR($F12="",$G12="",$H12=""),0,MIN(MAX(IF($F12>AQ$1,0,((($G12-$F12)-($G12-AQ$1))*(10/$E12)/10)),0),1)*$H12) -> 100 | AQ12: =IF(OR($H12=0,AP12=0),0,AP12/$H12) -> 1 | AR12: =IF(OR($F12="",$G12="",$H12=""),0,MIN(MAX(IF($F12>AS$1,0,((($G12-$F12)-($G12-AS$1))*(10/$E12)/10)),0),1)*$H12) -> 100 | AS12: =IF(OR($H12=0,AR12=0),0,AR12/$H12) -> 1 | AT12: =IF(OR($F12="",$G12="",$H12=""),0,MIN(MAX(IF($F12>AU$1,0,((($G12-$F12)-($G12-AU$1))*(10/$E12)/10)),0),1)*$H12) -> 100 | AU12: =IF(OR($H12=0,AT12=0),0,AT12/$H12) -> 1 | AV12: =IF(OR($F12="",$G12="",$H12=""),0,MIN(MAX(IF($F12>AW$1,0,((($G12-$F12)-($G12-AW$1))*(10/$E12)/10)),0),1)*$H12) -> 100 | AW12: =IF(OR($H12=0,AV12=0),0,AV12/$H12) -> 1 | AX12: =IF(OR($F12="",$G12="",$H12=""),0,MIN(MAX(IF($F12>AY$1,0,((($G12-$F12)-($G12-AY$1))*(10/$E12)/10)),0),1)*$H12) -> 100 | AY12: =IF(OR($H12=0,AX12=0),0,AX12/$H12) -> 1 | AZ12: =IF(OR($F12="",$G12="",$H12=""),0,MIN(MAX(IF($F12>BA$1,0,((($G12-$F12)-($G12-BA$1))*(10/$E12)/10)),0),1)*$H12) -> 100 | BA12: =IF(OR($H12=0,AZ12=0),0,AZ12/$H12) -> 1 | BB12: =IF(OR($F12="",$G12="",$H12=""),0,MIN(MAX(IF($F12>BC$1,0,((($G12-$F12)-($G12-BC$1))*(10/$E12)/10)),0),1)*$H12) -> 100 | BC12: =IF(OR($H12=0,BB12=0),0,BB12/$H12) -> 1 | BD12: =IF(OR($F12="",$G12="",$H12=""),0,MIN(MAX(IF($F12>BE$1,0,((($G12-$F12)-($G12-BE$1))*(10/$E12)/10)),0),1)*$H12) -> 100 | BE12: =IF(OR($H12=0,BD12=0),0,BD12/$H12) -> 1 | BF12: =IF(OR($F12="",$G12="",$H12=""),0,MIN(MAX(IF($F12>BG$1,0,((($G12-$F12)-($G12-BG$1))*(10/$E12)/10)),0),1)*$H12) -> 100 | BG12: =IF(OR($H12=0,BF12=0),0,BF12/$H12) -> 1 | BH12: =IF(OR($F12="",$G12="",$H12=""),0,MIN(MAX(IF($F12>BI$1,0,((($G12-$F12)-($G12-BI$1))*(10/$E12)/10)),0),1)*$H12) -> 100 | BI12: =IF(OR($H12=0,BH12=0),0,BH12/$H12) -> 1 | BJ12: =IF(OR($F12="",$G12="",$H12=""),0,MIN(MAX(IF($F12>BK$1,0,((($G12-$F12)-($G12-BK$1))*(10/$E12)/10)),0),1)*$H12) -> 100 | BK12: =IF(OR($H12=0,BJ12=0),0,BJ12/$H12) -> 1 | BL12: =IF(OR($F12="",$G12="",$H12=""),0,MIN(MAX(IF($F12>BM$1,0,((($G12-$F12)-($G12-BM$1))*(10/$E12)/10)),0),1)*$H12) -> 100 | BM12: =IF(OR($H12=0,BL12=0),0,BL12/$H12) -> 1 | BN12: =IF(OR($F12="",$G12="",$H12=""),0,MIN(MAX(IF($F12>BO$1,0,((($G12-$F12)-($G12-BO$1))*(10/$E12)/10)),0),1)*$H12) -> 100 | BO12: =IF(OR($H12=0,BN12=0),0,BN12/$H12) -> 1 | BP12: =IF(OR($F12="",$G12="",$H12=""),0,MIN(MAX(IF($F12>BQ$1,0,((($G12-$F12)-($G12-BQ$1))*(10/$E12)/10)),0),1)*$H12) -> 100 | BQ12: =IF(OR($H12=0,BP12=0),0,BP12/$H12) -> 1 | BR12: =IF(OR($F12="",$G12="",$H12=""),0,MIN(MAX(IF($F12>BS$1,0,((($G12-$F12)-($G12-BS$1))*(10/$E12)/10)),0),1)*$H12) -> 100 | BS12: =IF(OR($H12=0,BR12=0),0,BR12/$H12) -> 1 | BT12: =IF(OR($F12="",$G12="",$H12=""),0,MIN(MAX(IF($F12>BU$1,0,((($G12-$F12)-($G12-BU$1))*(10/$E12)/10)),0),1)*$H12) -> 100 | BU12: =IF(OR($H12=0,BT12=0),0,BT12/$H12) -> 1 | BV12: =IF(OR($F12="",$G12="",$H12=""),0,MIN(MAX(IF($F12>BW$1,0,((($G12-$F12)-($G12-BW$1))*(10/$E12)/10)),0),1)*$H12) -> 100 | BW12: =IF(OR($H12=0,BV12=0),0,BV12/$H12) -> 1 | BX12: =IF(OR($F12="",$G12="",$H12=""),0,MIN(MAX(IF($F12>BY$1,0,((($G12-$F12)-($G12-BY$1))*(10/$E12)/10)),0),1)*$H12) -> 100 | BY12: =IF(OR($H12=0,BX12=0),0,BX12/$H12) -> 1 | BZ12: =IF(OR($F12="",$G12="",$H12=""),0,MIN(MAX(IF($F12>CA$1,0,((($G12-$F12)-($G12-CA$1))*(10/$E12)/10)),0),1)*$H12) -> 100 | CA12: =IF(OR($H12=0,BZ12=0),0,BZ12/$H12) -> 1 | CB12: =IF(OR($F12="",$G12="",$H12=""),0,MIN(MAX(IF($F12>CC$1,0,((($G12-$F12)-($G12-CC$1))*(10/$E12)/10)),0),1)*$H12) -> 100 | CC12: =IF(OR($H12=0,CB12=0),0,CB12/$H12) -> 1 | CD12: =IF(OR($F12="",$G12="",$H12=""),0,MIN(MAX(IF($F12>CE$1,0,((($G12-$F12)-($G12-CE$1))*(10/$E12)/10)),0),1)*$H12) -> 100 | CE12: =IF(OR($H12=0,CD12=0),0,CD12/$H12) -> 1 | CF12: =IF(OR($F12="",$G12="",$H12=""),0,MIN(MAX(IF($F12>CG$1,0,((($G12-$F12)-($G12-CG$1))*(10/$E12)/10)),0),1)*$H12) -> 100 | CG12: =IF(OR($H12=0,CF12=0),0,CF12/$H12) -> 1 | CH12: =IF(OR($F12="",$G12="",$H12=""),0,MIN(MAX(IF($F12>CI$1,0,((($G12-$F12)-($G12-CI$1))*(10/$E12)/10)),0),1)*$H12) -> 100 | CI12: =IF(OR($H12=0,CH12=0),0,CH12/$H12) -> 1 | CJ12: =IF(OR($F12="",$G12="",$H12=""),0,MIN(MAX(IF($F12>CK$1,0,((($G12-$F12)-($G12-CK$1))*(10/$E12)/10)),0),1)*$H12) -> 100 | CK12: =IF(OR($H12=0,CJ12=0),0,CJ12/$H12) -> 1 | CL12: =IF(OR($F12="",$G12="",$H12=""),0,MIN(MAX(IF($F12>CM$1,0,((($G12-$F12)-($G12-CM$1))*(10/$E12)/10)),0),1)*$H12) -> 100 | CM12: =IF(OR($H12=0,CL12=0),0,CL12/$H12) -> 1
A13: =A12+1 -> 151 | B13: Completion of Piling | D13: 0 | E13: 1 | F13: 45271 | G13: 45271 | H13: 100 | I13: 100 | J13: % | K13: =IF(OR(F13="",G13="",H13=""),0,MIN(MAX(IF(F13>$O$1,0,(((G13-F13)-(G13-$O$1))*(10/E13)/10)),0),1)*H13) -> 100 | L13: =D13/$D$11 -> 0 | M13: =IF(OR(H13=0,K13=0),0,K13/H13) -> 1 | N13: =IF(OR(H13=0,I13=0),0,I13/H13) -> 1 | O13: =N13-M13 -> 0 | T13: =IF(OR($F13="",$G13="",$H13=""),0,MIN(MAX(IF($F13>U$1,0,((($G13-$F13)-($G13-U$1))*(10/$E13)/10)),0),1)*$H13) -> 0 | U13: =IF(OR($H13=0,T13=0),0,T13/$H13) -> 0 | V13: =IF(OR($F13="",$G13="",$H13=""),0,MIN(MAX(IF($F13>W$1,0,((($G13-$F13)-($G13-W$1))*(10/$E13)/10)),0),1)*$H13) -> 0 | W13: =IF(OR($H13=0,V13=0),0,V13/$H13) -> 0 | X13: =IF(OR($F13="",$G13="",$H13=""),0,MIN(MAX(IF($F13>Y$1,0,((($G13-$F13)-($G13-Y$1))*(10/$E13)/10)),0),1)*$H13) -> 0 | Y13: =IF(OR($H13=0,X13=0),0,X13/$H13) -> 0 | Z13: =IF(OR($F13="",$G13="",$H13=""),0,MIN(MAX(IF($F13>AA$1,0,((($G13-$F13)-($G13-AA$1))*(10/$E13)/10)),0),1)*$H13) -> 0 | AA13: =IF(OR($H13=0,Z13=0),0,Z13/$H13) -> 0 | AB13: =IF(OR($F13="",$G13="",$H13=""),0,MIN(MAX(IF($F13>AC$1,0,((($G13-$F13)-($G13-AC$1))*(10/$E13)/10)),0),1)*$H13) -> 0 | AC13: =IF(OR($H13=0,AB13=0),0,AB13/$H13) -> 0 | AD13: =IF(OR($F13="",$G13="",$H13=""),0,MIN(MAX(IF($F13>AE$1,0,((($G13-$F13)-($G13-AE$1))*(10/$E13)/10)),0),1)*$H13) -> 0 | AE13: =IF(OR($H13=0,AD13=0),0,AD13/$H13) -> 0 | AF13: =IF(OR($F13="",$G13="",$H13=""),0,MIN(MAX(IF($F13>AG$1,0,((($G13-$F13)-($G13-AG$1))*(10/$E13)/10)),0),1)*$H13) -> 0 | AG13: =IF(OR($H13=0,AF13=0),0,AF13/$H13) -> 0 | AH13: =IF(OR($F13="",$G13="",$H13=""),0,MIN(MAX(IF($F13>AI$1,0,((($G13-$F13)-($G13-AI$1))*(10/$E13)/10)),0),1)*$H13) -> 0 | AI13: =IF(OR($H13=0,AH13=0),0,AH13/$H13) -> 0 | AJ13: =IF(OR($F13="",$G13="",$H13=""),0,MIN(MAX(IF($F13>AK$1,0,((($G13-$F13)-($G13-AK$1))*(10/$E13)/10)),0),1)*$H13) -> 100 | AK13: =IF(OR($H13=0,AJ13=0),0,AJ13/$H13) -> 1 | AL13: =IF(OR($F13="",$G13="",$H13=""),0,MIN(MAX(IF($F13>AM$1,0,((($G13-$F13)-($G13-AM$1))*(10/$E13)/10)),0),1)*$H13) -> 100 | AM13: =IF(OR($H13=0,AL13=0),0,AL13/$H13) -> 1 | AN13: =IF(OR($F13="",$G13="",$H13=""),0,MIN(MAX(IF($F13>AO$1,0,((($G13-$F13)-($G13-AO$1))*(10/$E13)/10)),0),1)*$H13) -> 100 | AO13: =IF(OR($H13=0,AN13=0),0,AN13/$H13) -> 1 | AP13: =IF(OR($F13="",$G13="",$H13=""),0,MIN(MAX(IF($F13>AQ$1,0,((($G13-$F13)-($G13-AQ$1))*(10/$E13)/10)),0),1)*$H13) -> 100 | AQ13: =IF(OR($H13=0,AP13=0),0,AP13/$H13) -> 1 | AR13: =IF(OR($F13="",$G13="",$H13=""),0,MIN(MAX(IF($F13>AS$1,0,((($G13-$F13)-($G13-AS$1))*(10/$E13)/10)),0),1)*$H13) -> 100 | AS13: =IF(OR($H13=0,AR13=0),0,AR13/$H13) -> 1 | AT13: =IF(OR($F13="",$G13="",$H13=""),0,MIN(MAX(IF($F13>AU$1,0,((($G13-$F13)-($G13-AU$1))*(10/$E13)/10)),0),1)*$H13) -> 100 | AU13: =IF(OR($H13=0,AT13=0),0,AT13/$H13) -> 1 | AV13: =IF(OR($F13="",$G13="",$H13=""),0,MIN(MAX(IF($F13>AW$1,0,((($G13-$F13)-($G13-AW$1))*(10/$E13)/10)),0),1)*$H13) -> 100 | AW13: =IF(OR($H13=0,AV13=0),0,AV13/$H13) -> 1 | AX13: =IF(OR($F13="",$G13="",$H13=""),0,MIN(MAX(IF($F13>AY$1,0,((($G13-$F13)-($G13-AY$1))*(10/$E13)/10)),0),1)*$H13) -> 100 | AY13: =IF(OR($H13=0,AX13=0),0,AX13/$H13) -> 1 | AZ13: =IF(OR($F13="",$G13="",$H13=""),0,MIN(MAX(IF($F13>BA$1,0,((($G13-$F13)-($G13-BA$1))*(10/$E13)/10)),0),1)*$H13) -> 100 | BA13: =IF(OR($H13=0,AZ13=0),0,AZ13/$H13) -> 1 | BB13: =IF(OR($F13="",$G13="",$H13=""),0,MIN(MAX(IF($F13>BC$1,0,((($G13-$F13)-($G13-BC$1))*(10/$E13)/10)),0),1)*$H13) -> 100 | BC13: =IF(OR($H13=0,BB13=0),0,BB13/$H13) -> 1 | BD13: =IF(OR($F13="",$G13="",$H13=""),0,MIN(MAX(IF($F13>BE$1,0,((($G13-$F13)-($G13-BE$1))*(10/$E13)/10)),0),1)*$H13) -> 100 | BE13: =IF(OR($H13=0,BD13=0),0,BD13/$H13) -> 1 | BF13: =IF(OR($F13="",$G13="",$H13=""),0,MIN(MAX(IF($F13>BG$1,0,((($G13-$F13)-($G13-BG$1))*(10/$E13)/10)),0),1)*$H13) -> 100 | BG13: =IF(OR($H13=0,BF13=0),0,BF13/$H13) -> 1 | BH13: =IF(OR($F13="",$G13="",$H13=""),0,MIN(MAX(IF($F13>BI$1,0,((($G13-$F13)-($G13-BI$1))*(10/$E13)/10)),0),1)*$H13) -> 100 | BI13: =IF(OR($H13=0,BH13=0),0,BH13/$H13) -> 1 | BJ13: =IF(OR($F13="",$G13="",$H13=""),0,MIN(MAX(IF($F13>BK$1,0,((($G13-$F13)-($G13-BK$1))*(10/$E13)/10)),0),1)*$H13) -> 100 | BK13: =IF(OR($H13=0,BJ13=0),0,BJ13/$H13) -> 1 | BL13: =IF(OR($F13="",$G13="",$H13=""),0,MIN(MAX(IF($F13>BM$1,0,((($G13-$F13)-($G13-BM$1))*(10/$E13)/10)),0),1)*$H13) -> 100 | BM13: =IF(OR($H13=0,BL13=0),0,BL13/$H13) -> 1 | BN13: =IF(OR($F13="",$G13="",$H13=""),0,MIN(MAX(IF($F13>BO$1,0,((($G13-$F13)-($G13-BO$1))*(10/$E13)/10)),0),1)*$H13) -> 100 | BO13: =IF(OR($H13=0,BN13=0),0,BN13/$H13) -> 1 | BP13: =IF(OR($F13="",$G13="",$H13=""),0,MIN(MAX(IF($F13>BQ$1,0,((($G13-$F13)-($G13-BQ$1))*(10/$E13)/10)),0),1)*$H13) -> 100 | BQ13: =IF(OR($H13=0,BP13=0),0,BP13/$H13) -> 1 | BR13: =IF(OR($F13="",$G13="",$H13=""),0,MIN(MAX(IF($F13>BS$1,0,((($G13-$F13)-($G13-BS$1))*(10/$E13)/10)),0),1)*$H13) -> 100 | BS13: =IF(OR($H13=0,BR13=0),0,BR13/$H13) -> 1 | BT13: =IF(OR($F13="",$G13="",$H13=""),0,MIN(MAX(IF($F13>BU$1,0,((($G13-$F13)-($G13-BU$1))*(10/$E13)/10)),0),1)*$H13) -> 100 | BU13: =IF(OR($H13=0,BT13=0),0,BT13/$H13) -> 1 | BV13: =IF(OR($F13="",$G13="",$H13=""),0,MIN(MAX(IF($F13>BW$1,0,((($G13-$F13)-($G13-BW$1))*(10/$E13)/10)),0),1)*$H13) -> 100 | BW13: =IF(OR($H13=0,BV13=0),0,BV13/$H13) -> 1 | BX13: =IF(OR($F13="",$G13="",$H13=""),0,MIN(MAX(IF($F13>BY$1,0,((($G13-$F13)-($G13-BY$1))*(10/$E13)/10)),0),1)*$H13) -> 100 | BY13: =IF(OR($H13=0,BX13=0),0,BX13/$H13) -> 1 | BZ13: =IF(OR($F13="",$G13="",$H13=""),0,MIN(MAX(IF($F13>CA$1,0,((($G13-$F13)-($G13-CA$1))*(10/$E13)/10)),0),1)*$H13) -> 100 | CA13: =IF(OR($H13=0,BZ13=0),0,BZ13/$H13) -> 1 | CB13: =IF(OR($F13="",$G13="",$H13=""),0,MIN(MAX(IF($F13>CC$1,0,((($G13-$F13)-($G13-CC$1))*(10/$E13)/10)),0),1)*$H13) -> 100 | CC13: =IF(OR($H13=0,CB13=0),0,CB13/$H13) -> 1 | CD13: =IF(OR($F13="",$G13="",$H13=""),0,MIN(MAX(IF($F13>CE$1,0,((($G13-$F13)-($G13-CE$1))*(10/$E13)/10)),0),1)*$H13) -> 100 | CE13: =IF(OR($H13=0,CD13=0),0,CD13/$H13) -> 1 | CF13: =IF(OR($F13="",$G13="",$H13=""),0,MIN(MAX(IF($F13>CG$1,0,((($G13-$F13)-($G13-CG$1))*(10/$E13)/10)),0),1)*$H13) -> 100 | CG13: =IF(OR($H13=0,CF13=0),0,CF13/$H13) -> 1 | CH13: =IF(OR($F13="",$G13="",$H13=""),0,MIN(MAX(IF($F13>CI$1,0,((($G13-$F13)-($G13-CI$1))*(10/$E13)/10)),0),1)*$H13) -> 100 | CI13: =IF(OR($H13=0,CH13=0),0,CH13/$H13) -> 1 | CJ13: =IF(OR($F13="",$G13="",$H13=""),0,MIN(MAX(IF($F13>CK$1,0,((($G13-$F13)-($G13-CK$1))*(10/$E13)/10)),0),1)*$H13) -> 100 | CK13: =IF(OR($H13=0,CJ13=0),0,CJ13/$H13) -> 1 | CL13: =IF(OR($F13="",$G13="",$H13=""),0,MIN(MAX(IF($F13>CM$1,0,((($G13-$F13)-($G13-CM$1))*(10/$E13)/10)),0),1)*$H13) -> 100 | CM13: =IF(OR($H13=0,CL13=0),0,CL13/$H13) -> 1
A14: =A13+1 -> 152 | B14: Substructure | D14: 812 | E14: 62 | F14: 45276 | G14: 45337 | L14: =D14/$D$10 -> 0.99145299 | M14: =$L15*M15+$L36*M36+$L50*M50+$L81*M81 -> 1 | N14: =$L15*N15+$L36*N36+$L50*N50+$L81*N81 -> 1 | O14: =N14-M14 -> 0 | U14: =$L15*U15+$L36*U36+$L50*U50+$L81*U81 -> 0 | W14: =$L15*W15+$L36*W36+$L50*W50+$L81*W81 -> 0 | Y14: =$L15*Y15+$L36*Y36+$L50*Y50+$L81*Y81 -> 0 | AA14: =$L15*AA15+$L36*AA36+$L50*AA50+$L81*AA81 -> 0 | AC14: =$L15*AC15+$L36*AC36+$L50*AC50+$L81*AC81 -> 0 | AE14: =$L15*AE15+$L36*AE36+$L50*AE50+$L81*AE81 -> 0 | AG14: =$L15*AG15+$L36*AG36+$L50*AG50+$L81*AG81 -> 0 | AI14: =$L15*AI15+$L36*AI36+$L50*AI50+$L81*AI81 -> 0 | AK14: =$L15*AK15+$L36*AK36+$L50*AK50+$L81*AK81 -> 0 | AM14: =$L15*AM15+$L36*AM36+$L50*AM50+$L81*AM81 -> 0.016009852 | AO14: =$L15*AO15+$L36*AO36+$L50*AO50+$L81*AO81 -> 0.082512315 | AQ14: =$L15*AQ15+$L36*AQ36+$L50*AQ50+$L81*AQ81 -> 0.18842365 | AS14: =$L15*AS15+$L36*AS36+$L50*AS50+$L81*AS81 -> 0.34605911 | AU14: =$L15*AU15+$L36*AU36+$L50*AU50+$L81*AU81 -> 0.5270936 | AW14: =$L15*AW15+$L36*AW36+$L50*AW50+$L81*AW81 -> 0.72536946 | AY14: =$L15*AY15+$L36*AY36+$L50*AY50+$L81*AY81 -> 0.87315271 | BA14: =$L15*BA15+$L36*BA36+$L50*BA50+$L81*BA81 -> 0.96305419 | BC14: =$L15*BC15+$L36*BC36+$L50*BC50+$L81*BC81 -> 1 | BE14: =$L15*BE15+$L36*BE36+$L50*BE50+$L81*BE81 -> 1 | BG14: =$L15*BG15+$L36*BG36+$L50*BG50+$L81*BG81 -> 1 | BI14: =$L15*BI15+$L36*BI36+$L50*BI50+$L81*BI81 -> 1 | BK14: =$L15*BK15+$L36*BK36+$L50*BK50+$L81*BK81 -> 1 | BM14: =$L15*BM15+$L36*BM36+$L50*BM50+$L81*BM81 -> 1 | BO14: =$L15*BO15+$L36*BO36+$L50*BO50+$L81*BO81 -> 1 | BQ14: =$L15*BQ15+$L36*BQ36+$L50*BQ50+$L81*BQ81 -> 1 | BS14: =$L15*BS15+$L36*BS36+$L50*BS50+$L81*BS81 -> 1 | BU14: =$L15*BU15+$L36*BU36+$L50*BU50+$L81*BU81 -> 1 | BW14: =$L15*BW15+$L36*BW36+$L50*BW50+$L81*BW81 -> 1 | BY14: =$L15*BY15+$L36*BY36+$L50*BY50+$L81*BY81 -> 1 | CA14: =$L15*CA15+$L36*CA36+$L50*CA50+$L81*CA81 -> 1 | CC14: =$L15*CC15+$L36*CC36+$L50*CC50+$L81*CC81 -> 1 | CE14: =$L15*CE15+$L36*CE36+$L50*CE50+$L81*CE81 -> 1 | CG14: =$L15*CG15+$L36*CG36+$L50*CG50+$L81*CG81 -> 1 | CI14: =$L15*CI15+$L36*CI36+$L50*CI50+$L81*CI81 -> 1 | CK14: =$L15*CK15+$L36*CK36+$L50*CK50+$L81*CK81 -> 1 | CM14: =$L15*CM15+$L36*CM36+$L50*CM50+$L81*CM81 -> 1
A15: =A14+1 -> 153 | B15: Structure | D15: 313 | E15: 56 | F15: 45276 | G15: 45331 | L15: =D15/$D$14 -> 0.38546798 | M15: =$L16*M16+$L27*M27+$L35*M35 -> 1 | N15: =$L16*N16+$L27*N27+$L35*N35 -> 1 | O15: =N15-M15 -> 0 | U15: =$L16*U16+$L27*U27+$L35*U35 -> 0 | W15: =$L16*W16+$L27*W27+$L35*W35 -> 0 | Y15: =$L16*Y16+$L27*Y27+$L35*Y35 -> 0 | AA15: =$L16*AA16+$L27*AA27+$L35*AA35 -> 0 | AC15: =$L16*AC16+$L27*AC27+$L35*AC35 -> 0 | AE15: =$L16*AE16+$L27*AE27+$L35*AE35 -> 0 | AG15: =$L16*AG16+$L27*AG27+$L35*AG35 -> 0 | AI15: =$L16*AI16+$L27*AI27+$L35*AI35 -> 0 | AK15: =$L16*AK16+$L27*AK27+$L35*AK35 -> 0 | AM15: =$L16*AM16+$L27*AM27+$L35*AM35 -> 0.03514377 | AO15: =$L16*AO16+$L27*AO27+$L35*AO35 -> 0.1341853 | AQ15: =$L16*AQ16+$L27*AQ27+$L35*AQ35 -> 0.28434505 | AS15: =$L16*AS16+$L27*AS27+$L35*AS35 -> 0.46964856 | AU15: =$L16*AU16+$L27*AU27+$L35*AU35 -> 0.6485623 | AW15: =$L16*AW16+$L27*AW27+$L35*AW35 -> 0.82747604 | AY15: =$L16*AY16+$L27*AY27+$L35*AY35 -> 0.93929712 | BA15: =$L16*BA16+$L27*BA27+$L35*BA35 -> 0.99680511 | BC15: =$L16*BC16+$L27*BC27+$L35*BC35 -> 1 | BE15: =$L16*BE16+$L27*BE27+$L35*BE35 -> 1 | BG15: =$L16*BG16+$L27*BG27+$L35*BG35 -> 1 | BI15: =$L16*BI16+$L27*BI27+$L35*BI35 -> 1 | BK15: =$L16*BK16+$L27*BK27+$L35*BK35 -> 1 | BM15: =$L16*BM16+$L27*BM27+$L35*BM35 -> 1 | BO15: =$L16*BO16+$L27*BO27+$L35*BO35 -> 1 | BQ15: =$L16*BQ16+$L27*BQ27+$L35*BQ35 -> 1 | BS15: =$L16*BS16+$L27*BS27+$L35*BS35 -> 1 | BU15: =$L16*BU16+$L27*BU27+$L35*BU35 -> 1 | BW15: =$L16*BW16+$L27*BW27+$L35*BW35 -> 1 | BY15: =$L16*BY16+$L27*BY27+$L35*BY35 -> 1 | CA15: =$L16*CA16+$L27*CA27+$L35*CA35 -> 1 | CC15: =$L16*CC16+$L27*CC27+$L35*CC35 -> 1 | CE15: =$L16*CE16+$L27*CE27+$L35*CE35 -> 1 | CG15: =$L16*CG16+$L27*CG27+$L35*CG35 -> 1 | CI15: =$L16*CI16+$L27*CI27+$L35*CI35 -> 1 | CK15: =$L16*CK16+$L27*CK27+$L35*CK35 -> 1 | CM15: =$L16*CM16+$L27*CM27+$L35*CM35 -> 1
